Workbook

Sheet README
A1: Audit-Evidence Tracker (PBC)
A2: Wrenfield Health (fictional) · simulated NIST SP 800-53 Rev. 5 (Release 5.2.0) assessment · synthetic data
A4: As-of (status) date | B4: 46283 | C4: <- input: all aging/overdue formulas reference this cell (use =TODAY() in a live workbook)
A6: Statuses | B6: Not Requested, Requested, Received, Under Review, Accepted, Insufficient, Rework Required, Closed
A7: Evidence level | B7: Design = documentation exists; Implementation = configured/deployed; Operating Effectiveness = worked over the period. See audit/evidence-quality-guide.md
A8: Sufficiency | B8: Derived: Accepted/Closed = Sufficient; Insufficient/Rework = Insufficient; others Pending
A9: Days Late | B9: Live formula: received after due, or still outstanding past due as of the README date
A10: Completion % | B10: (Accepted + Closed) / all requested items. 'Insufficient' is NOT complete: it becomes a finding
A11: Locations | B11: Paths starting with evidence/ or access-review/ are synthetic samples committed in this repo; 'GRC-Vault:/' paths are the fictional evidence vault

Sheet Evidence
A1: Evidence ID | B1: Control ID | C1: Evidence Request | D1: Artifact Description | E1: Evidence Owner | F1: Request Date | G1: Due Date | H1: Received Date | I1: Status | J1: Evidence Period | K1: File / Repository Location | L1: In Repo? | M1: Reviewer | N1: Review Result | O1: Evidence Level | P1: Sufficiency | Q1: Exception | R1: Follow-Up Required | S1: Days Late | T1: Notes
A2: EVID-001 | B2: AC-1 | C2: Current Access Control Policy with approval record and review history | D2: ACP-002 Access Control Policy v3.1 (PDF) + approval minutes 2025-01-15 | E2: Alicia Moreno | F2: 46183 | G2: 46192 | H2: 46185 | I2: Accepted | J2: Current version | K2: GRC-Vault:/WCP-2026/AC/EVID-001_ACP-002_v3.1.pdf | L2: No | M2: Lead assessor | N2: Content adequate; last approval 2025-01-15 exceeds the annual review cycle | O2: Design | P2: Sufficient | R2: No | S2: =IF(H2="",MAX(0,README!$B$4-G2),MAX(0,H2-G2)) | T2: Drives OBS-01. Policy existence alone did not satisfy AC-2 or AC-6
A3: EVID-002 | B3: AC-2; AC-2(3); PS-4; PS-5 | C3: Joiner/mover/leaver procedure | D3: SOP-IAM-02 Account Lifecycle v2.0 | E3: Nadia Rahman | F3: 46183 | G3: 46192 | H3: 46185 | I3: Accepted | J3: Current version | K3: GRC-Vault:/WCP-2026/AC/EVID-002_SOP-IAM-02_v2.0.pdf | L3: No | M3: Lead assessor | N3: Describes a manual HR-email to IT-ticket flow; no step for local accounts or transfers | O3: Design | P3: Sufficient | R3: No | S3: =IF(H3="",MAX(0,README!$B$4-G3),MAX(0,H3-G3)) | T3: Design gap is visible in the procedure itself
A4: EVID-003 | B4: AC-2(3); PS-4 | C4: System-generated list of ALL terminations 2026-01-01 to 2026-06-30 (worker ID, type, date, effective time) | D4: PeopleHub report 'Terminations by Effective Date' + final-pay reconciliation | E4: Denise Yamamoto | F4: 46183 | G4: 46192 | H4: 46190 | I4: Accepted | J4: 2026-01-01 to 2026-06-30 | K4: evidence/AC/EVID-003_peoplehub-terminations-2026H1.csv | L4: Yes | M4: Lead assessor | N4: IPE validated: 19 of 19 reconciled to final pay/invoice | O4: Operating Effectiveness | P4: Sufficient | R4: No | S4: =IF(H4="",MAX(0,README!$B$4-G4),MAX(0,H4-G4)) | T4: Assessor observed report generation over screen share
A5: EVID-004 | B5: AC-2(3) | C5: Okta System Log export of user.lifecycle.deactivate events for the period | D5: Okta System Log API export | E5: Nadia Rahman | F5: 46183 | G5: 46192 | H5: 46190 | I5: Accepted | J5: 2026-01-01 to 2026-06-30 | K5: evidence/AC/EVID-004_okta-deactivation-events-2026H1.csv | L5: Yes | M5: Lead assessor | N5: 17 events; matched to EVID-003 | O5: Operating Effectiveness | P5: Sufficient | R5: No | S5: =IF(H5="",MAX(0,README!$B$4-G5),MAX(0,H5-G5))
A6: EVID-005 | B6: AC-2; AC-2(1); IA-2; AC-6(2) | C6: Okta user export (all statuses) with MFA enrollment and group membership as of 2026-06-30 | D6: Okta Users API export | E6: Nadia Rahman | F6: 46183 | G6: 46192 | H6: 46204 | I6: Accepted | J6: As of 2026-06-30 | K6: access-review/source-exports/okta_users.csv | L6: Yes | M6: Lead assessor | N6: Complete for in-scope population; account types verified | O6: Implementation | P6: Sufficient | R6: No | S6: =IF(H6="",MAX(0,README!$B$4-G6),MAX(0,H6-G6))
A7: EVID-006 | B7: AC-2; AC-6; AC-6(5) | C7: Entitlement exports from each in-scope system as of 2026-06-30 | D7: Exports from AWS IAM Identity Center/IAM, GitHub, Aurora roles, wf-sftp-01, PeopleHub, Ledgerline, SIEM, EDR, Quarrystone portal | E7: System owners (9 systems) | F7: 46183 | G7: 46204 | H7: 46206 | I7: Accepted | J7: As of 2026-06-30 | K7: access-review/source-exports/entitlements.csv | L7: Yes | M7: Lead assessor | N7: 106 entitlements; 2 exports re-pulled after column omissions (Ledgerline, portal) | O7: Implementation | P7: Sufficient | R7: No | S7: =IF(H7="",MAX(0,README!$B$4-G7),MAX(0,H7-G7)) | T7: Ledgerline export first omitted role assignment dates; returned 2026-07-03
A8: EVID-007 | B8: AC-2; IA-2(1); IA-5 | C8: AWS IAM credential report for wcp-prod | D8: IAM credential report (CSV) | E8: Tomasz Wierzbicki | F8: 46183 | G8: 46192 | H8: 46204 | I8: Accepted | J8: As of 2026-06-30 | K8: evidence/IA/EVID-007_aws-iam-credential-report_2026-06-30.csv | L8: Yes | M8: Lead assessor | N8: Revealed mfeld-admin (no MFA) and svc-reporting-etl static key | O8: Implementation | P8: Sufficient | R8: No | S8: =IF(H8="",MAX(0,README!$B$4-G8),MAX(0,H8-G8))
A9: EVID-008 | B9: AC-6(7) | C9: Q1 2026 access certification campaign export (reviewer, item, decision, timestamp) | D9: Okta Access Certification campaign export Q1-2026 (412 decisions) | E9: Alicia Moreno | F9: 46183 | G9: 46192 | H9: 46197 | I9: Accepted | J9: 2026-03-02 to 2026-03-20 | K9: evidence/AC/EVID-008_q1-certification-summary.md | L9: Yes | M9: Lead assessor | N9: 100% approved; 17 of 23 reviewers finished in under 5 minutes; approved 2 items later found invalid | O9: Operating Effectiveness | P9: Sufficient | R9: No | S9: =IF(H9="",MAX(0,README!$B$4-G9),MAX(0,H9-G9))
A10: EVID-009 | B10: AC-6(7) | C10: Evidence that quarterly access reviews are performed | D10: Screenshot: 'Q1 Access Review, 100% complete' dashboard tile | E10: Alicia Moreno | F10: 46183 | G10: 46192 | H10: 46188 | I10: Insufficient | J10: Undated | K10: evidence/AC/EVID-009_insufficient-screenshot-example.md | L10: Yes | M10: Lead assessor | N10: No population, reviewers, decisions, or date; cannot show review quality | O10: Design | P10: Insufficient | Q10: Screenshot shows completion status only | R10: Yes: replaced by EVID-008 | S10: =IF(H10="",MAX(0,README!$B$4-G10),MAX(0,H10-G10)) | T10: Teaching example: completion does not prove effectiveness
A11: EVID-010 | B11: IA-2(1); IA-2(2); IA-2(8) | C11: Okta authentication and global session policy export | D11: Okta Policies API export | E11: Nadia Rahman | F11: 46183 | G11: 46192 | H11: 46203 | I11: Accepted | J11: As of 2026-06-30 | K11: evidence/IA/EVID-010_okta-authentication-policies_2026-06-30.json | L11: Yes | M11: Lead assessor | N11: Global policy excludes MFA-Exempt-Legacy group; admin apps accept non-phishing-resistant factors | O11: Implementation | P11: Sufficient | R11: No | S11: =IF(H11="",MAX(0,README!$B$4-G11),MAX(0,H11-G11))
A12: EVID-011 | B12: IA-2(1); IA-2(2) | C12: Membership of all MFA exemption groups with reason and approval | D12: Okta group membership export MFA-Exempt-Legacy | E12: Nadia Rahman | F12: 46183 | G12: 46192 | H12: 46203 | I12: Accepted | J12: As of 2026-06-30 | K12: evidence/IA/EVID-011_okta-mfa-exempt-group_2026-06-30.csv | L12: Yes | M12: Lead assessor | N12: 11 members (9 human, 2 service); 0 approvals or expiry dates | O12: Implementation | P12: Sufficient | R12: No | S12: =IF(H12="",MAX(0,README!$B$4-G12),MAX(0,H12-G12))
A13: EVID-012 | B13: IA-2(8) | C13: Enabled authenticator configuration | D13: Okta authenticator settings export | E13: Nadia Rahman | F13: 46183 | G13: 46192 | H13: 46203 | I13: Accepted | J13: As of 2026-06-30 | K13: GRC-Vault:/WCP-2026/IA/EVID-012_okta-authenticators.json | L13: No | M13: Lead assessor | N13: Only replay-resistant factors enabled; SMS/voice disabled | O13: Implementation | P13: Sufficient | R13: No | S13: =IF(H13="",MAX(0,README!$B$4-G13),MAX(0,H13-G13))
A14: EVID-013 | B14: AC-2; IA-5 | C14: Service-account register with owner, purpose, credential type, and last rotation | D14: Service account register v2026-06 | E14: Nadia Rahman | F14: 46183 | G14: 46199 | H14: 46211 | I14: Accepted | J14: As of 2026-06-30 | K14: access-review/source-exports/service_accounts.csv | L14: Yes | M14: Lead assessor | N14: Accepted after rework | O14: Implementation | P14: Sufficient | R14: No | S14: =IF(H14="",MAX(0,README!$B$4-G14),MAX(0,H14-G14)) | T14: First submission (2026-06-25) lacked owner and rotation columns; returned as Rework Required; accepted 2026-07-08
A15: EVID-014 | B15: AC-5 | C15: Ledgerline role and permission matrix and SoD ruleset | D15: Ledgerline security role report + SoD matrix | E15: Laura Brenneman | F15: 46183 | G15: 46192 | H15: 46191 | I15: Accepted | J15: Current | K15: access-review/source-exports/sod_rules.csv | L15: Yes | M15: Lead assessor | N15: Rules adequate; conflict detected in assignments | O15: Design | P15: Sufficient | R15: No | S15: =IF(H15="",MAX(0,README!$B$4-G15),MAX(0,H15-G15))
A16: EVID-015 | B16: AC-5 | C16: Monthly vendor-master change reports with reviewer sign-off (Jan–Jun) | D16: 6 signed Ledgerline vendor-master change reports | E16: Laura Brenneman | F16: 46183 | G16: 46192 | H16: 46195 | I16: Accepted | J16: 2026-01 to 2026-06 | K16: GRC-Vault:/WCP-2026/AC/EVID-015_vendor-master-reviews-H1.pdf | L16: No | M16: Lead assessor | N16: 6 of 6 signed by Controller within 10 days of month end; 2 bank-detail changes verified by callback | O16: Operating Effectiveness | P16: Sufficient | R16: No | S16: =IF(H16="",MAX(0,README!$B$4-G16),MAX(0,H16-G16))
A17: EVID-016 | B17: AC-6; AC-6(2); AC-6(5) | C17: AWS IAM Identity Center permission-set assignments for wcp-prod | D17: Identity Center assignment export | E17: Tomasz Wierzbicki | F17: 46183 | G17: 46192 | H17: 46204 | I17: Accepted | J17: As of 2026-06-30 | K17: access-review/source-exports/entitlements.csv | L17: Yes | M17: Lead assessor | N17: Admin assignments exceed role definitions | O17: Implementation | P17: Sufficient | R17: No | S17: =IF(H17="",MAX(0,README!$B$4-G17),MAX(0,H17-G17))
A18: EVID-017 | B18: AC-6(5) | C18: GitHub organization owners and repository admins | D18: GitHub org member export (role=owner/admin) | E18: Grace Lindqvist | F18: 46183 | G18: 46192 | H18: 46204 | I18: Accepted | J18: As of 2026-06-30 | K18: access-review/source-exports/entitlements.csv | L18: Yes | M18: Lead assessor | N18: 5 owners vs maximum 3 | O18: Implementation | P18: Sufficient | R18: No | S18: =IF(H18="",MAX(0,README!$B$4-G18),MAX(0,H18-G18))
A19: EVID-018 | B19: AC-17 | C19: Remote administrative access architecture and session logging configuration | D19: SSM Session Manager preferences + network exposure report | E19: Tomasz Wierzbicki | F19: 46183 | G19: 46192 | H19: 46197 | I19: Accepted | J19: As of 2026-06-30 | K19: GRC-Vault:/WCP-2026/AC/EVID-018_ssm-session-prefs.json | L19: No | M19: Lead assessor | N19: Sessions logged and encrypted; no public bastions | O19: Implementation | P19: Sufficient | R19: No | S19: =IF(H19="",MAX(0,README!$B$4-G19),MAX(0,H19-G19))
A20: EVID-019 | B20: AT-2 | C20: LMS completion report for annual security awareness (full workforce) and phishing simulation results | D20: LMS report + simulation summary | E20: Denise Yamamoto | F20: 46183 | G20: 46192 | H20: 46199 | I20: Accepted | J20: FY2026 cycle as of 2026-06-30 | K20: GRC-Vault:/WCP-2026/AT/EVID-019_lms-completion-2026-06-30.csv | L20: No | M20: Lead assessor | N20: 316 of 347 complete (91%); 4 overdue users hold PHI access | O20: Operating Effectiveness | P20: Sufficient | R20: No | S20: =IF(H20="",MAX(0,README!$B$4-G20),MAX(0,H20-G20))
A21: EVID-020 | B21: AT-3 | C21: Role-based training completion for engineers, admins, clinical/support staff | D21: LMS role-group reports | E21: Denise Yamamoto | F21: 46183 | G21: 46192 | H21: 46199 | I21: Accepted | J21: 2026-01-01 to 2026-06-30 | K21: GRC-Vault:/WCP-2026/AT/EVID-020_role-training.csv | L21: No | M21: Lead assessor | N21: 15 of 15 sampled complete | O21: Operating Effectiveness | P21: Sufficient | R21: No | S21: =IF(H21="",MAX(0,README!$B$4-G21),MAX(0,H21-G21))
A22: EVID-021 | B22: AU-2 | C22: Logging standard, trail configurations, and sample events for required types | D22: LMS-004 + CloudTrail/EKS/app-audit configs + 10 traced events | E22: Owen Castillo | F22: 46183 | G22: 46192 | H22: 46197 | I22: Accepted | J22: As of 2026-06-30 | K22: GRC-Vault:/WCP-2026/AU/EVID-021_logging-config-and-samples.zip | L22: No | M22: Lead assessor | N22: 10 of 10 required event types present with required fields | O22: Implementation | P22: Sufficient | R22: No | S22: =IF(H22="",MAX(0,README!$B$4-G22),MAX(0,H22-G22))
A23: EVID-022 | B23: AU-6 | C23: All weekly privileged-activity review tickets W01–W26 | D23: SEC ticket export | E23: Owen Castillo | F23: 46183 | G23: 46192 | H23: 46199 | I23: Accepted | J23: 2026-W01 to 2026-W26 | K23: evidence/AU/EVID-022_privileged-activity-reviews-2026H1.csv | L23: Yes | M23: Lead assessor | N23: 19 of 26 performed; 17 of 26 fully effective | O23: Operating Effectiveness | P23: Sufficient | R23: No | S23: =IF(H23="",MAX(0,README!$B$4-G23),MAX(0,H23-G23))
A24: EVID-023 | B24: AU-9 | C24: Log archive bucket protections and SCPs | D24: S3 Object Lock config + bucket policy + SCP JSON | E24: Owen Castillo | F24: 46183 | G24: 46192 | H24: 46197 | I24: Accepted | J24: As of 2026-06-30 | K24: GRC-Vault:/WCP-2026/AU/EVID-023_log-archive-protections.json | L24: No | M24: Lead assessor | N24: Compliance-mode Object Lock; StopLogging denied | O24: Implementation | P24: Sufficient | R24: No | S24: =IF(H24="",MAX(0,README!$B$4-G24),MAX(0,H24-G24))
A25: EVID-024 | B25: AU-11 | C25: Retention settings for every audit source plus oldest available record per source | D25: SIEM retention setting + S3 lifecycle + CloudWatch retention + oldest-record queries | E25: Owen Castillo | F25: 46183 | G25: 46192 | H25: 46198 | I25: Accepted | J25: As of 2026-06-30 | K25: evidence/AU/EVID-024_log-retention-config_2026-06-30.json | L25: Yes | M25: Lead assessor | N25: Retention 90–180 days vs 12-month requirement | O25: Implementation | P25: Sufficient | R25: No | S25: =IF(H25="",MAX(0,README!$B$4-G25),MAX(0,H25-G25))
A26: EVID-025 | B26: CA-2 | C26: Most recent SOC 2 Type II report and external penetration test report | D26: SOC 2 Type II (2024-10-01 to 2025-09-30) + 2025 pentest summary and retest letter | E26: Priya Raman | F26: 46183 | G26: 46192 | H26: 46185 | I26: Accepted | J26: FY2025 | K26: GRC-Vault:/WCP-2026/CA/EVID-025_soc2-and-pentest.pdf | L26: No | M26: Lead assessor | N26: Independent assessments at defined frequency | O26: Operating Effectiveness | P26: Sufficient | R26: No | S26: =IF(H26="",MAX(0,README!$B$4-G26),MAX(0,H26-G26))
... A33: EVID-032 | B33: CP-2 | C33: Current BC/DR plan | D33: BCP-003 v2.1 (2025-11) | E33: Tomasz Wierzbicki | F33: 46183 | G33: 46192 | H33: 46185 | I33: Accepted | J33: Current version | K33: GRC-Vault:/WCP-2026/CP/EVID-032_BCP-003_v2.1.pdf | L33: No | M33: Lead assessor | N33: Adequate design with RTO 4h / RPO 1h | O33: Design | P33: Sufficient | R33: No | S33: =IF(H33="",MAX(0,README!$B$4-G33),MAX(0,H33-G33))
A34: EVID-033 | B34: CP-4 | C34: Contingency plan test records (last 24 months) | D34: 2024-04 AZ failover engineering notes | E34: Tomasz Wierzbicki | F34: 46183 | G34: 46192 | H34: 46199 | I34: Insufficient | J34: 2024-07-01 to 2026-06-30 | K34: GRC-Vault:/WCP-2026/CP/EVID-033_az-failover-notes-2024.md | L34: No | M34: Lead assessor | N34: No plan-level test within 12 months; notes are not an after-action report | O34: Design | P34: Insufficient | Q34: No CP test in period | R34: Yes: POAM-014 | S34: =IF(H34="",MAX(0,README!$B$4-G34),MAX(0,H34-G34))
A35: EVID-034 | B35: CP-9 | C35: Backup plans, job history (30 days), vault protections | D35: AWS Backup plan JSON + job history + Vault Lock config | E35: Tomasz Wierzbicki | F35: 46183 | G35: 46192 | H35: 46197 | I35: Accepted | J35: 2026-06-01 to 2026-06-30 | K35: GRC-Vault:/WCP-2026/CP/EVID-034_backup-config.zip | L35: No | M35: Lead assessor | N35: 30 of 30 jobs successful; Vault Lock compliance mode | O35: Operating Effectiveness | P35: Sufficient | R35: No | S35: =IF(H35="",MAX(0,README!$B$4-G35),MAX(0,H35-G35))
A36: EVID-035 | B36: CP-9(1) | C36: Backup restore test records | D36: Backup job success notifications (no restore records) | E36: Tomasz Wierzbicki | F36: 46183 | G36: 46192 | H36: 46199 | I36: Insufficient | J36: 2025-07-01 to 2026-06-30 | K36: GRC-Vault:/WCP-2026/CP/EVID-035_backup-job-notifications.pdf | L36: No | M36: Lead assessor | N36: A successful backup job is not a tested restore | O36: Implementation | P36: Insufficient | Q36: No restore test ever documented | R36: Yes: POAM-013 | S36: =IF(H36="",MAX(0,README!$B$4-G36),MAX(0,H36-G36))
A37: EVID-036 | B37: IR-8 | C37: Current incident response plan with review history | D37: IRP-005 v4.0 (reviewed 2025-11) | E37: Owen Castillo | F37: 46183 | G37: 46192 | H37: 46185 | I37: Accepted | J37: Current version | K37: GRC-Vault:/WCP-2026/IR/EVID-036_IRP-005_v4.0.pdf | L37: No | M37: Lead assessor | N37: Current; stale contact roster (OBS-03) | O37: Design | P37: Sufficient | R37: No | S37: =IF(H37="",MAX(0,README!$B$4-G37),MAX(0,H37-G37))
A38: EVID-037 | B38: IR-3 | C38: IR test/exercise records (last 24 months) | D38: 2024-09-18 tabletop after-action report | E38: Owen Castillo | F38: 46183 | G38: 46192 | H38: 46199 | I38: Insufficient | J38: 2024-07-01 to 2026-06-30 | K38: GRC-Vault:/WCP-2026/IR/EVID-037_tabletop-2024-09.pdf | L38: No | M38: Lead assessor | N38: Most recent exercise 21 months before fieldwork | O38: Design | P38: Insufficient | Q38: No IR test in 12 months | R38: Yes: POAM-014 | S38: =IF(H38="",MAX(0,README!$B$4-G38),MAX(0,H38-G38))
A39: EVID-038 | B39: IR-4; IR-6; SI-3 | C39: All incident tickets for the period with timelines and notifications | D39: Incident register export (6 incidents) | E39: Owen Castillo | F39: 46183 | G39: 46192 | H39: 46199 | I39: Accepted | J39: 2026-01-01 to 2026-06-30 | K39: evidence/IR/EVID-038_incident-tickets-2026H1.csv | L39: Yes | M39: Lead assessor | N39: 6 of 6 handled per plan; notification timely | O39: Operating Effectiveness | P39: Sufficient | R39: No | S39: =IF(H39="",MAX(0,README!$B$4-G39),MAX(0,H39-G39))
A40: EVID-039 | B40: MP-6 | C40: Certificates of destruction for all devices retired in the period | D40: 14 Coldwater certificates + MDM retired-device list | E40: Kevin Brandt | F40: 46183 | G40: 46192 | H40: 46195 | I40: Accepted | J40: 2026-01-01 to 2026-06-30 | K40: GRC-Vault:/WCP-2026/MP/EVID-039_itad-certificates.pdf | L40: No | M40: Lead assessor | N40: 14 of 14 reconciled by serial | O40: Operating Effectiveness | P40: Sufficient | R40: No | S40: =IF(H40="",MAX(0,README!$B$4-G40),MAX(0,H40-G40))
A41: EVID-040 | B41: PE-3; MP-6; AC-18 | C41: Inherited-control record and provider attestation review log; boundary definition | D41: Control inheritance record + 2026-03 attestation review note + boundary diagram | E41: Priya Raman | F41: 46183 | G41: 46192 | H41: 46188 | I41: Accepted | J41: Current | K41: docs/scope/system-profile.md | L41: Yes | M41: Lead assessor | N41: Inheritance documented and reviewed | O41: Design | P41: Sufficient | R41: No | S41: =IF(H41="",MAX(0,README!$B$4-G41),MAX(0,H41-G41))
A42: EVID-041 | B42: PL-2 | C42: Current system security plan | D42: SSP v1.3 (2025-02) | E42: Priya Raman | F42: 46183 | G42: 46192 | H42: 46185 | I42: Accepted | J42: Current version | K42: GRC-Vault:/WCP-2026/PL/EVID-041_SSP_v1.3.pdf | L42: No | M42: Lead assessor | N42: Outdated: 3 architecture changes missing; 27 of 61 controls overstated vs testing | O42: Design | P42: Sufficient | R42: No | S42: =IF(H42="",MAX(0,README!$B$4-G42),MAX(0,H42-G42))
A43: EVID-042 | B43: PM-9 | C43: Risk management strategy and Board-approved risk appetite | D43: RMS-001 + Risk Appetite Statement (Board minutes 2025-10-21) | E43: Alicia Moreno | F43: 46183 | G43: 46192 | H43: 46185 | I43: Accepted | J43: Current | K43: GRC-Vault:/WCP-2026/PM/EVID-042_RMS-001_and_appetite.pdf | L43: No | M43: Lead assessor | N43: Adequate; applied in RACC-001 and VR-001 escalation | O43: Design | P43: Sufficient | R43: No | S43: =IF(H43="",MAX(0,README!$B$4-G43),MAX(0,H43-G43))
A44: EVID-043 | B44: PS-3 | C44: Background-check completion for 15 sampled H1 hires/contractors | D44: Screening vendor reports + Northgate attestations | E44: Denise Yamamoto | F44: 46183 | G44: 46192 | H44: 46195 | I44: Accepted | J44: 2026-01-01 to 2026-06-30 | K44: GRC-Vault:/WCP-2026/PS/EVID-043_screening-sample.pdf | L44: No | M44: Lead assessor | N44: 15 of 15 screened before access | O44: Operating Effectiveness | P44: Sufficient | R44: No | S44: =IF(H44="",MAX(0,README!$B$4-G44),MAX(0,H44-G44))
A45: EVID-044 | B45: PS-5 | C45: All transfers in period with before/after access | D45: PeopleHub transfer report (6) + access tickets | E45: Denise Yamamoto | F45: 46183 | G45: 46192 | H45: 46195 | I45: Accepted | J45: 2026-01-01 to 2026-06-30 | K45: GRC-Vault:/WCP-2026/PS/EVID-044_transfers.csv | L45: No | M45: Lead assessor | N45: 1 of 6 retained prior-role PHI access | O45: Operating Effectiveness | P45: Sufficient | R45: No | S45: =IF(H45="",MAX(0,README!$B$4-G45),MAX(0,H45-G45))
A46: EVID-045 | B46: PS-7 | C46: Contractor roster with SOW start/end dates and scope | D46: Northgate SOW register (5 contractors active in H1) | E46: Sofia Ricci | F46: 46183 | G46: 46192 | H46: 46195 | I46: Accepted | J46: 2026-01-01 to 2026-06-30 | K46: GRC-Vault:/WCP-2026/PS/EVID-045_contractor-sow-register.xlsx | L46: No | M46: Lead assessor | N46: End dates not enforced in Okta; scope not mapped to access | O46: Implementation | P46: Sufficient | R46: No | S46: =IF(H46="",MAX(0,README!$B$4-G46),MAX(0,H46-G46))
...
