Workbook

Sheet README
A1: Plan of Action & Milestones (POA&M)
A2: Wrenfield Health (fictional) · simulated NIST SP 800-53 Rev. 5 (Release 5.2.0) assessment · synthetic data
A4: As-of (status) date | B4: 46283 | C4: <- input: all aging/overdue formulas reference this cell (use =TODAY() in a live workbook)
A6: Scope | B6: Every finding (FIND-nnn) has POAM-nnn, including the risk-accepted item: nothing silently drops off
A7: SLA | B7: From Open Date: Critical 30 / High 90 / Moderate 180 / Low 365 days (RSK-MTH-001 §9). SLA Date is a live formula
A8: Original vs current target | B8: Original target never changes. A changed current target needs a documented, approved reason; 'Slipped?' is a formula
A9: Percent Complete | B9: Formula: milestones Done / total milestones (Milestones sheet). No subjective percentages
A10: Overdue? | B10: Formula: status not Closed/Risk Accepted AND current target < as-of date
A11: Closure rule | B11: Status 'Closed' only after assessor validation with closure evidence (see Validation Method)

Sheet POAM
A1: POA&M ID | B1: Related Finding | C1: Related Control | D1: Related Risk | E1: Weakness | F1: Root Cause | G1: Severity | H1: Corrective Action | I1: Milestones | J1: Owner | K1: Resources Required | L1: Open Date | M1: SLA Date | N1: Original Target Date | O1: Current Target Date | P1: Target Change Reason | Q1: Current Status | R1: Percent Complete | S1: Days Open | T1: Overdue? | U1: Slipped? | V1: Target Within SLA? | W1: Dependencies | X1: Validation Method | Y1: Closure Evidence | Z1: Validated By | AA1: Closure Date | AB1: Residual Risk | AC1: Notes
A2: POAM-001 | B2: FIND-001 | C2: AC-2(3); AC-2; AC-2(1); PS-4; PS-7 | D2: RISK-002 | E2: Terminated workforce retained active access (SSO, local AWS IAM, vendor portal) | F2: Manual HR-email-to-IT ticketing with no automated trigger; local accounts not in offboarding checklist; contractor end dates not enforced | G2: High | H2: Disable identified accounts; implement daily HR-to-Okta/AWS/portal reconciliation with auto-ticketing; update SOP-IAM-02 with a local-account checklist and 24h SLA | I2: M1 Disable 4 identified accounts (AR-EX-01..04); investigate post-termination sign-in (INC-2026-0117) (due 2026-07-10; Done) | M2 Deploy daily HR-to-Okta/AWS IAM/portal reconciliation job with auto-ticketing (due 2026-08-21; Done) | M3 Update SOP-IAM-02 (24h SLA, local-account checklist, vendor portals); train IT (due 2026-08-28; Done) | M4 Assessor validation: re-perform termination test on all terminations since 2026-07-01 + 5 job runs (due 2026-09-11; Done) | J2: Nadia Rahman (IAM Engineer) | K2: IAM Engineer (about 60h); Okta Workflows (existing license); HR ops (4h) | L2: 46241 | M2: =L2+IF(G2="Critical",30,IF(G2="High",90,IF(G2="Moderate",180,365))) | N2: 46276 | O2: 46276 | Q2: Closed | R2: =IFERROR(COUNTIFS(Milestones!$A:$A,A2,Milestones!$E:$E,"Done")/COUNTIF(Milestones!$A:$A,A2),0) | S2: =IF(Q2="Closed",AA2-L2,README!$B$4-L2) | T2: =IF(AND(Q2<>"Closed",Q2<>"Risk Accepted",O2<README!$B$4),"Yes","No") | U2: =IF(O2<>N2,"Yes","No") | V2: =IF(Q2="Risk Accepted","n/a (acceptance expiry)",IF(O2<=M2,"Yes","No")) | W2: Okta Workflows connector to PeopleHub | X2: Re-performance: tools/assessment_tests.py termination-validation (7 of 7 within 24h, 0 job exceptions); inspection of IAM credential report (break-glass only) | Y2: EVID-061; EVID-062; EVID-064; EVID-078 | Z2: Lead assessor | AA2: 46275 | AB2: Moderate (RISK-002 residual L2 x I4 = 8) | AC2: Operating sample is small (7); full re-test scheduled for FY27.
A3: POAM-002 | B3: FIND-002 | C3: IA-2(1); IA-2(2) | D3: RISK-003 | E3: MFA exemption group and AWS IAM user without MFA | F3: Exceptions granted without workflow, expiry, or review; legacy IAM users bypass Okta policy | G3: High | H3: Delete exemption policy and group; enroll all members (hardware key accommodation); convert service users to integrations; require phishing-resistant MFA for admin apps; delete non-break-glass IAM users; add time-bound exception workflow | I3: M1 Enroll 9 human members in MFA (accommodation for 1) (due 2026-08-28; Done) | M2 Convert svc-vulnscan and svc-confroom to non-interactive integrations (due 2026-08-28; Done) | M3 Delete Legacy Exemption Policy and group; phishing-resistant policy on admin apps (CHG-2026-0731) (due 2026-09-01; Done) | M4 Assessor validation: policy export, group lookup, password-only sign-in attempt, IAM credential report (due 2026-09-05; Done) | J3: Nadia Rahman (IAM Engineer) | K3: IAM Engineer (about 30h); 12 FIDO2 keys (about $600) | L3: 46241 | M3: =L3+IF(G3="Critical",30,IF(G3="High",90,IF(G3="Moderate",180,365))) | N3: 46270 | O3: 46270 | Q3: Closed | R3: =IFERROR(COUNTIFS(Milestones!$A:$A,A3,Milestones!$E:$E,"Done")/COUNTIF(Milestones!$A:$A,A3),0) | S3: =IF(Q3="Closed",AA3-L3,README!$B$4-L3) | T3: =IF(AND(Q3<>"Closed",Q3<>"Risk Accepted",O3<README!$B$4),"Yes","No") | U3: =IF(O3<>N3,"Yes","No") | V3: =IF(Q3="Risk Accepted","n/a (acceptance expiry)",IF(O3<=M3,"Yes","No")) | W3: Hardware key delivery for accessibility accommodation | X3: Inspection of Okta policy export and IAM credential report; re-performance of password-only sign-in with a test account (denied) | Y3: EVID-063; EVID-064 | Z3: Lead assessor | AA3: 46270 | AB3: Moderate (RISK-003 residual L2 x I4 = 8)
A4: POAM-003 | B4: FIND-003 | C4: AC-6(5); AC-6; AC-6(2) | D4: RISK-001 | E4: Excessive privileged access; administration from daily-use accounts | F4: Privileged grants without expiry; no privileged-access review before 2026; separate-admin policy never rolled out | G4: High | H4: Remove excess grants; issue -adm accounts with phishing-resistant MFA; implement approval-gated JIT elevation for AWS admin; enforce GitHub owner cap | I4: M1 Remove excess grants: AR-EX-05/06/07/08/09 (due 2026-08-21; Done) | M2 Issue -adm accounts for remaining admins; remove admin from daily accounts (AR-EX-10) (due 2026-09-30; In Progress) | M3 Implement JIT elevation (approval + 4h auto-expiry) for AWS AdministratorAccess (due 2026-10-23; In Progress) | M4 Assessor validation: assignment export + live elevation record with CloudTrail evidence (due 2026-11-05; Not Started) | J4: Tomasz Wierzbicki (Director, Platform Engineering) | K4: SRE (about 80h); IAM Engineer (about 20h) | L4: 46241 | M4: =L4+IF(G4="Critical",30,IF(G4="High",90,IF(G4="Moderate",180,365))) | N4: 46331 | O4: 46331 | Q4: In Progress | R4: =IFERROR(COUNTIFS(Milestones!$A:$A,A4,Milestones!$E:$E,"Done")/COUNTIF(Milestones!$A:$A,A4),0) | S4: =IF(Q4="Closed",AA4-L4,README!$B$4-L4) | T4: =IF(AND(Q4<>"Closed",Q4<>"Risk Accepted",O4<README!$B$4),"Yes","No") | U4: =IF(O4<>N4,"Yes","No") | V4: =IF(Q4="Risk Accepted","n/a (acceptance expiry)",IF(O4<=M4,"Yes","No")) | W4: IAM Identity Center permission-set redesign; EVID-071 returned as Rework Required (design-only evidence) | X4: Inspection of Identity Center/GitHub/Okta admin exports; re-performance: request and observe a JIT elevation, confirm auto-expiry in CloudTrail | Y4: EVID-075; EVID-076; EVID-077; EVID-071 | AB4: Moderate target (RISK-001 residual L2 x I4 = 8); currently High | AC4: Evidence EVID-071 rejected: a screenshot of an approval screen shows the design, not that elevation operates.
A5: POAM-004 | B5: FIND-004 | C5: AC-6(7); AC-2; PS-5 | D5: RISK-004 | E5: Access recertification incomplete in scope and ineffective in operation | F5: Campaign scope limited to Okta app assignments; no usage data or risk flags for reviewers; no transfer trigger | G5: Moderate | H5: Redesign certification to cover all privileged and PHI entitlements on 9 systems with usage and baseline flags; require rationale for approving flagged items; transfer-triggered re-certification | I5: M1 Revoke duplicate, transferred, and inactive access (AR-EX-12/13/14) (due 2026-07-17; Done) | M2 Add transfer trigger to SOP-IAM-02 (re-baseline access within 5 business days) (due 2026-08-28; Done) | M3 Run Q3 privileged certification on new design (EVID-074) (due 2026-09-30; In Progress) | M4 Assessor validation: review Q3 campaign decisions for flagged items and rationale quality (due 2026-10-31; Not Started) | J5: Alicia Moreno (CISO) | K5: GRC Manager (about 40h); IAM Engineer (about 30h); review_engine.py reused as the flagging logic | L5: 46241 | M5: =L5+IF(G5="Critical",30,IF(G5="High",90,IF(G5="Moderate",180,365))) | N5: 46326 | O5: 46326 | Q5: In Progress | R5: =IFERROR(COUNTIFS(Milestones!$A:$A,A5,Milestones!$E:$E,"Done")/COUNTIF(Milestones!$A:$A,A5),0) | S5: =IF(Q5="Closed",AA5-L5,README!$B$4-L5) | T5: =IF(AND(Q5<>"Closed",Q5<>"Risk Accepted",O5<README!$B$4),"Yes","No") | U5: =IF(O5<>N5,"Yes","No") | V5: =IF(Q5="Risk Accepted","n/a (acceptance expiry)",IF(O5<=M5,"Yes","No")) | W5: Q3 campaign completion by reviewers | X5: Inspection of campaign export (population completeness vs entitlement exports; % flagged items with rationale; removals actioned) | Y5: EVID-061; EVID-074 | AB5: Moderate (RISK-004 residual L2 x I3 = 6)
A6: POAM-005 | B6: FIND-005 | C6: IA-5; AC-2 | D6: RISK-017 | E6: Service/shared accounts without owners, stale credentials, shared vendor login | F6: Service register lacked owner/rotation fields; vendor access set up for convenience | G6: Moderate | H6: Assign owners; rotate or federate stale credentials; named federated accounts for MDR analysts; add owner/rotation fields and quarterly attestation to the register | I6: M1 Assign owners to all 13 non-human accounts; add fields to register (due 2026-08-21; Done) | M2 Rotate svc-quarrystone-sftp key (AR-EX-18) (due 2026-08-28; Done) | M3 Replace ironpeak-soc shared login with 6 named federated accounts (AR-EX-20) (due 2026-09-04; Done) | M4 Migrate svc-reporting-etl to IAM role; delete IAM user (AR-EX-19) (due 2026-09-11; Done) | M5 Assessor validation: register re-test (owner + credential age) and IAM credential report (due 2026-09-12; Done) | J6: Nadia Rahman (IAM Engineer) | K6: IAM Engineer (about 20h); SRE (about 16h) | L6: 46241 | M6: =L6+IF(G6="Critical",30,IF(G6="High",90,IF(G6="Moderate",180,365))) | N6: 46277 | O6: 46277 | Q6: Closed | R6: =IFERROR(COUNTIFS(Milestones!$A:$A,A6,Milestones!$E:$E,"Done")/COUNTIF(Milestones!$A:$A,A6),0) | S6: =IF(Q6="Closed",AA6-L6,README!$B$4-L6) | T6: =IF(AND(Q6<>"Closed",Q6<>"Risk Accepted",O6<README!$B$4),"Yes","No") | U6: =IF(O6<>N6,"Yes","No") | V6: =IF(Q6="Risk Accepted","n/a (acceptance expiry)",IF(O6<=M6,"Yes","No")) | W6: Ironpeak MDR SSO onboarding | X6: Re-performance of the review engine's service-account checks on the updated register; inspection of EDR console user list (no shared logins) | Y6: EVID-065; EVID-064 | Z6: Lead assessor | AA6: 46277 | AB6: Low (RISK-017 residual L1 x I4 = 4)
A7: POAM-006 | B7: FIND-006 | C7: PS-7; AC-2 | D7: RISK-002; RISK-004 | E7: Contractor access not bound to engagement term and scope | F7: Contract end dates not enforced in Okta; access requests not checked against SOW scope | G7: Moderate | H7: Okta account expiry = SOW end date for all contractors; SOW scope required on contractor access requests; monthly contractor roster to sponsors | I7: M1 Execute SOW amendment for awu; revoke out-of-scope PHI access (AR-EX-15/16) (due 2026-07-24; Done) | M2 Set Okta expiry for all contractor accounts; add SOW-scope field to access request form (due 2026-08-28; Done) | M3 Assessor validation: expiry report vs SOW register (due 2026-09-10; Done) | J7: Sofia Ricci (Engineering Manager) | K7: IAM Engineer (about 8h); Vendor Mgmt (about 4h) | L7: 46241 | M7: =L7+IF(G7="Critical",30,IF(G7="High",90,IF(G7="Moderate",180,365))) | N7: 46275 | O7: 46275 | Q7: Closed | R7: =IFERROR(COUNTIFS(Milestones!$A:$A,A7,Milestones!$E:$E,"Done")/COUNTIF(Milestones!$A:$A,A7),0) | S7: =IF(Q7="Closed",AA7-L7,README!$B$4-L7) | T7: =IF(AND(Q7<>"Closed",Q7<>"Risk Accepted",O7<README!$B$4),"Yes","No") | U7: =IF(O7<>N7,"Yes","No") | V7: =IF(Q7="Risk Accepted","n/a (acceptance expiry)",IF(O7<=M7,"Yes","No")) | X7: Inspection: Okta expiry dates reconciled to SOW register for all active contractors (29 of 29) | Y7: EVID-066 | Z7: Lead assessor | AA7: 46275 | AB7: Moderate (RISK-002 residual)
A8: POAM-007 | B8: FIND-007 | C8: AC-5 | D8: RISK-013 | E8: SoD conflict (vendor master + payment approval) | F8: Finance team reduced to 3 after AP departure | G8: Moderate | H8: Formal risk acceptance (RACC-001) with compensating monthly independent review; split roles when AP role is backfilled | I8: M1 Sign RACC-001 (CFO as risk owner; CISO concurrence) (due 2026-08-14; Done) | M2 Continue monthly compensating review (evidence each month to GRC) (due 2027-03-31; In Progress) | M3 Split roles at AP backfill (requisition open) (due 2027-03-31; Not Started) | J8: Laura Brenneman (Controller) | K8: Controller (2h/month for compensating review) | L8: 46241 | M8: =L8+IF(G8="Critical",30,IF(G8="High",90,IF(G8="Moderate",180,365))) | N8: 46477 | O8: 46477 | Q8: Risk Accepted | R8: =IFERROR(COUNTIFS(Milestones!$A:$A,A8,Milestones!$E:$E,"Done")/COUNTIF(Milestones!$A:$A,A8),0) | S8: =IF(Q8="Closed",AA8-L8,README!$B$4-L8) | T8: =IF(AND(Q8<>"Closed",Q8<>"Risk Accepted",O8<README!$B$4),"Yes","No") | U8: =IF(O8<>N8,"Yes","No") | V8: =IF(Q8="Risk Accepted","n/a (acceptance expiry)",IF(O8<=M8,"Yes","No")) | W8: AP Specialist hire | X8: Monthly: GRC inspects signed vendor-master change report; at expiry: re-test role assignments | Y8: EVID-060; EVID-015 | AB8: Moderate, accepted (RISK-013 residual L2 x I3 = 6) | AC8: Accepted risks stay on the POA&M until expiry so they are re-decided, not forgotten.
A9: POAM-008 | B9: FIND-008 | C9: AU-11 | D9: RISK-005 | E9: Audit log retention below 12-month requirement | F9: 2022 cost-driven retention settings never revisited after contractual requirements emerged | G9: Moderate | H9: 400-day lifecycle with tiering (hot 90d searchable); archive application audit logs to log-archive; quarterly oldest-record check | I9: M1 Change S3 lifecycle to 400-day expiry with Glacier IR after 90d (CHG-2026-0702) (due 2026-08-21; Done) | M2 Subscribe app-audit CloudWatch logs to log-archive (Firehose) (due 2026-08-28; Done) | M3 Assessor validation: config inspection + oldest-object query (due 2026-09-15; Done) | J9: Owen Castillo (Security Engineer) | K9: Security Engineer (about 16h); storage cost about $180/month | L9: 46241 | M9: =L9+IF(G9="Critical",30,IF(G9="High",90,IF(G9="Moderate",180,365))) | N9: 46280 | O9: 46280 | Q9: Closed | R9: =IFERROR(COUNTIFS(Milestones!$A:$A,A9,Milestones!$E:$E,"Done")/COUNTIF(Milestones!$A:$A,A9),0) | S9: =IF(Q9="Closed",AA9-L9,README!$B$4-L9) | T9: =IF(AND(Q9<>"Closed",Q9<>"Risk Accepted",O9<README!$B$4),"Yes","No") | U9: =IF(O9<>N9,"Yes","No") | V9: =IF(Q9="Risk Accepted","n/a (acceptance expiry)",IF(O9<=M9,"Yes","No")) | X9: Inspection of lifecycle/subscription config; test: oldest CloudTrail object (2026-03-20, 182 days) still present after old 180-day rule would have expired it | Y9: EVID-067 | Z9: Lead assessor | AA9: 46280 | AB9: Moderate (RISK-005 residual after POAM-009) | AC9: Full 12-month retention can only be demonstrated over time; FY27 assessment re-tests.
A10: POAM-009 | B10: FIND-009 | C10: AU-6 | D10: RISK-005 | E10: Weekly privileged-activity review missed 7 of 26 weeks; 2 incomplete | F10: Single reviewer; no escalation; scope excluded local IAM users | G10: Moderate | H10: Backup reviewer (MDR under SOW change); auto-created weekly ticket with 5-day escalation; expand scope to all privileged principals; disposition required per flag | I10: M1 Expand SIEM report scope to all privileged principals incl. IAM users (due 2026-08-21; Done) | M2 Auto-create weekly review ticket with escalation to CISO at 5 business days (due 2026-08-28; Done) | M3 Execute MDR SOW change for backup reviewer (due 2026-09-11; Delayed) | M4 Assessor validation: W27–W37 reviews (EVID-072) (due 2026-09-15; Not Started) | J10: Owen Castillo (Security Engineer) | K10: MDR SOW change (about $1,500/month); Security Engineer (about 12h) | L10: 46241 | M10: =L10+IF(G10="Critical",30,IF(G10="High",90,IF(G10="Moderate",180,365))) | N10: 46280 | O10: 46280 | Q10: In Progress | R10: =IFERROR(COUNTIFS(Milestones!$A:$A,A10,Milestones!$E:$E,"Done")/COUNTIF(Milestones!$A:$A,A10),0) | S10: =IF(Q10="Closed",AA10-L10,README!$B$4-L10) | T10: =IF(AND(Q10<>"Closed",Q10<>"Risk Accepted",O10<README!$B$4),"Yes","No") | U10: =IF(O10<>N10,"Yes","No") | V10: =IF(Q10="Risk Accepted","n/a (acceptance expiry)",IF(O10<=M10,"Yes","No")) | W10: Procurement approval of MDR SOW change (pending CFO signature) | X10: Test: all weeks since change performed within 5 days with dispositions; inspect escalation config | Y10: EVID-072 | AB10: Moderate (RISK-005 residual L2 x I3 = 6) | AC10: Overdue since 2026-09-15; escalated to CISO 2026-09-16.
A11: POAM-010 | B11: FIND-010 | C11: SI-2 | D11: RISK-006 | E11: 23% of Critical/High vulnerabilities exceeded SLA; exception process unused | F11: End-of-life runtimes block patching; no exception discipline; SLA not visible in engineering planning; 7% untagged assets | G11: High | H11: Upgrade notify-worker runtime; file exceptions with reachability analysis where justified; SLA dashboard in sprint planning; tag-policy SCP | I11: M1 Submit VM-003 §7 exception for 2 notify-worker criticals with reachability analysis (CISO decision) (due 2026-08-21; Done) | M2 Upgrade notify-worker to supported Node.js LTS + current base image (due 2026-09-30; In Progress) | M3 SLA-breach dashboard reviewed in weekly engineering leads meeting (due 2026-09-15; Done) | M4 Tag-policy SCP denying untagged EC2/EKS launches (OBS-02) (due 2026-10-15; Not Started) | M5 Assessor validation: re-run SLA test on Q3 population (due 2026-11-05; Not Started) | J11: Grace Lindqvist (VP Engineering) | K11: Engineering (about 3 sprint-weeks); Security Engineer (about 16h) | L11: 46241 | M11: =L11+IF(G11="Critical",30,IF(G11="High",90,IF(G11="Moderate",180,365))) | N11: 46331 | O11: 46331 | Q11: In Progress | R11: =IFERROR(COUNTIFS(Milestones!$A:$A,A11,Milestones!$E:$E,"Done")/COUNTIF(Milestones!$A:$A,A11),0) | S11: =IF(Q11="Closed",AA11-L11,README!$B$4-L11) | T11: =IF(AND(Q11<>"Closed",Q11<>"Risk Accepted",O11<README!$B$4),"Yes","No") | U11: =IF(O11<>N11,"Yes","No") | V11: =IF(Q11="Risk Accepted","n/a (acceptance expiry)",IF(O11<=M11,"Yes","No")) | W11: FIND-011 (4 open breaches resolve only when legacy hosts are decommissioned) | X11: Re-performance: tools/assessment_tests.py vulnsla on Q3 export (target: >= 95% within SLA, 0 open Critical past SLA without exception) | AB11: Moderate (RISK-006 residual L2 x I4 = 8) | AC11: CISO approved a 30-day exception for the 2 criticals (expires 2026-09-30) contingent on M2; consider SI-2(7) root cause analysis (OBS-04).
A12: POAM-011 | B12: FIND-011 | C12: SA-22 | D12: RISK-007 | E12: Unsupported components (Windows 2012 R2 SFTP host, PostgreSQL 11, Node.js 16) in PHI path | F12: Legacy integrations excluded from modernization; no lifecycle review for non-IaC assets | G12: High | H12: Avoid: replace wf-sftp-01 with managed transfer (IaC, PGP + SFTP, vendor/customer keys); migrate legacy-reports to supported Aurora replica; upgrade notify-worker (with POAM-010); maintain compensating controls until then | I12: M1 Stand up managed transfer service (IaC) and test with Quarrystone (due 2026-08-28; Done) | M2 Cut over Quarrystone + 4 customers; decommission wf-sftp-01 (due 2026-09-15; Delayed) | M3 Migrate legacy-reports to Aurora read replica; decommission EC2 host (due 2026-10-30; In Progress) | M4 Assessor validation: inventory shows 0 unsupported components; hosts terminated (due 2026-12-15; Not Started) | J12: Tomasz Wierzbicki (Director, Platform Engineering) | K12: SRE (about 120h); Customer Ops coordination with 4 customers + Quarrystone; managed transfer service about $400/month | L12: 46241 | M12: =L12+IF(G12="Critical",30,IF(G12="High",90,IF(G12="Moderate",180,365))) | N12: 46331 | O12: 46371 | P12: M2 slipped: 2 of 4 customers have not completed partner key exchange. SLA extension approved by CTO and CISO 2026-09-12 with compensating controls (EDR, allowlist, SSM-only admin, weekly scans); still ahead of SHCA go-live 2027-01-11. | Q12: Delayed | R12: =IFERROR(COUNTIFS(Milestones!$A:$A,A12,Milestones!$E:$E,"Done")/COUNTIF(Milestones!$A:$A,A12),0) | S12: =IF(Q12="Closed",AA12-L12,README!$B$4-L12) | T12: =IF(AND(Q12<>"Closed",Q12<>"Risk Accepted",O12<README!$B$4),"Yes","No") | U12: =IF(O12<>N12,"Yes","No") | V12: =IF(Q12="Risk Accepted","n/a (acceptance expiry)",IF(O12<=M12,"Yes","No")) | W12: Customer partner-side key exchange (2 of 4 pending); POAM-010 M2 for notify-worker | X12: Inspection of EOL inventory and AWS Config (instances terminated); re-run vulnsla to confirm legacy-host findings closed | AB12: Low target (RISK-007 residual L1 x I4 = 4); currently High | AC12: Treatment is Avoid (decommission) rather than patching, which is not possible.
A13: POAM-012 | B13: FIND-012 | C13: SC-7; CM-6 | D13: RISK-012; RISK-007 | E13: RDP open to 0.0.0.0/0 on wf-sftp-01; CSPM High finding untriaged 43 days | F13: Console change path bypasses IaC/approval; Security Hub findings not routed to on-call | G13: High | H13: Remove rule; route Security Hub High findings to on-call with 7-day SLA; SCP guardrail blocking 0.0.0.0/0 on admin ports | I13: M1 Remove 3389 ingress rule; confirm SSM-only admin (CHG-2026-0521); review Windows 4624 type-10 logons (due 2026-07-03; Done) | M2 Route Security Hub High findings to SRE on-call queue (due 2026-07-08; Done) | M3 Deploy SCP guardrail for admin ports from 0.0.0.0/0 (due 2026-07-10; Done) | M4 Assessor validation: SG export, Security Hub PASSED, guardrail test (due 2026-07-10; Done) | J13: Tomasz Wierzbicki (Director, Platform Engineering) | K13: SRE (about 12h) | L13: 46205 | M13: =L13+IF(G13="Critical",30,IF(G13="High",90,IF(G13="Moderate",180,365))) | N13: 46213 | O13: 46213 | Q13: Closed | R13: =IFERROR(COUNTIFS(Milestones!$A:$A,A13,Milestones!$E:$E,"Done")/COUNTIF(Milestones!$A:$A,A13),0) | S13: =IF(Q13="Closed",AA13-L13,README!$B$4-L13) | T13: =IF(AND(Q13<>"Closed",Q13<>"Risk Accepted",O13<README!$B$4),"Yes","No") | U13: =IF(O13<>N13,"Yes","No") | V13: =IF(Q13="Risk Accepted","n/a (acceptance expiry)",IF(O13<=M13,"Yes","No")) | X13: Inspection of SG and Security Hub status; re-performance: attempted to add 0.0.0.0/0:3389 rule in a sandbox OU account (denied by SCP) | Y13: EVID-068; EVID-053 | Z13: Lead assessor | AA13: 46213 | AB13: Moderate (RISK-012 residual L2 x I4 = 8) | AC13: Remediated during fieldwork. Still reported as a finding because the control failed during the period.
A14: POAM-013 | B14: FIND-013 | C14: CP-9(1) | D14: RISK-008 | E14: Backup restoration never tested | F14: Recoverability assumed from job success; no scheduled restore test | G14: Moderate | H14: Documented restore from DR vault into isolated account with timing and integrity checks; semi-annual schedule in BCP-003 | I14: M1 Write restore runbook and integrity-check queries (due 2026-08-21; Done) | M2 Perform restore test (assessor observes) (due 2026-08-28; Done) | M3 Add semi-annual restore test to BCP-003 calendar; assessor validation (due 2026-09-01; Done) | J14: Tomasz Wierzbicki (Director, Platform Engineering) | K14: SRE (about 16h); isolated recovery account | L14: 46241 | M14: =L14+IF(G14="Critical",30,IF(G14="High",90,IF(G14="Moderate",180,365))) | N14: 46266 | O14: 46266 | Q14: Closed | R14: =IFERROR(COUNTIFS(Milestones!$A:$A,A14,Milestones!$E:$E,"Done")/COUNTIF(Milestones!$A:$A,A14),0) | S14: =IF(Q14="Closed",AA14-L14,README!$B$4-L14) | T14: =IF(AND(Q14<>"Closed",Q14<>"Risk Accepted",O14<README!$B$4),"Yes","No") | U14: =IF(O14<>N14,"Yes","No") | V14: =IF(Q14="Risk Accepted","n/a (acceptance expiry)",IF(O14<=M14,"Yes","No")) | X14: Observation of restore test; inspection of timings vs RTO/RPO and integrity check output | Y14: EVID-069 | Z14: Lead assessor | AA14: 46266 | AB14: Moderate (RISK-008 residual L2 x I4 = 8, pending POAM-014)
A15: POAM-014 | B15: FIND-014 | C15: IR-3; CP-4 | D15: RISK-009; RISK-008 | E15: IR and contingency plans not tested in 12+ months; SHCA 24h path unrehearsed | F15: Exercises deferred twice without escalation | G15: Moderate | H15: Combined ransomware tabletop (IR + CP) with MDR, Legal/Privacy, Customer Ops, execs; update IRP-005 (SHCA 24h step, roster); track after-action items | I15: M1 Update IRP-005: SHCA 24h notification step + current roster (OBS-03) (due 2026-09-15; Done) | M2 Conduct ransomware tabletop (IR + CP) (due 2026-10-14; Not Started) | M3 Publish after-action report; add corrective actions to POA&M (due 2026-10-30; Not Started) | M4 Assessor validation (due 2026-11-15; Not Started) | J15: Owen Castillo (Security Engineer) | K15: Facilitator (MDR-provided, in contract); 3h of 12 participants | L15: 46241 | M15: =L15+IF(G15="Critical",30,IF(G15="High",90,IF(G15="Moderate",180,365))) | N15: 46341 | O15: 46341 | Q15: In Progress | R15: =IFERROR(COUNTIFS(Milestones!$A:$A,A15,Milestones!$E:$E,"Done")/COUNTIF(Milestones!$A:$A,A15),0) | S15: =IF(Q15="Closed",AA15-L15,README!$B$4-L15) | T15: =IF(AND(Q15<>"Closed",Q15<>"Risk Accepted",O15<README!$B$4),"Yes","No") | U15: =IF(O15<>N15,"Yes","No") | V15: =IF(Q15="Risk Accepted","n/a (acceptance expiry)",IF(O15<=M15,"Yes","No")) | W15: Executive calendar availability | X15: Inspection of exercise materials, attendance, after-action report; verify corrective actions are tracked | AB15: Moderate (RISK-009 residual L2 x I3 = 6)
A16: POAM-015 | B16: FIND-015 | C16: SR-6; SA-9; SR-2 | D16: RISK-011; RISK-010 | E16: 5 of 14 Tier 1–2 vendors overdue; no fourth-party inventory; no C-SCRM plan | F16: Under-resourced vendor program; spreadsheet tracking without reminders | G16: Moderate | H16: Clear overdue assessments (Tier 1 first); build fourth-party inventory; approve C-SCRM plan aligned to SP 800-161r1-upd1 / SP 800-18r2; renewal triggers | I16: M1 Assess Tier 1 overdue vendors (Pulsewire, Ironpeak) (due 2026-11-30; In Progress) | M2 Fourth-party inventory from updated questionnaires (all Tier 1) (due 2026-12-15; Not Started) | M3 Approve C-SCRM plan (due 2027-01-15; Not Started) | M4 Assess remaining Tier 2 overdue vendors; assessor validation (due 2027-02-03; Not Started) | J16: Beth Kowalski (Vendor Management Lead) | K16: Vendor Mgmt (about 0.5 FTE for 4 months); GRC Manager support | L16: 46241 | M16: =L16+IF(G16="Critical",30,IF(G16="High",90,IF(G16="Moderate",180,365))) | N16: 46421 | O16: 46421 | Q16: In Progress | R16: =IFERROR(COUNTIFS(Milestones!$A:$A,A16,Milestones!$E:$E,"Done")/COUNTIF(Milestones!$A:$A,A16),0) | S16: =IF(Q16="Closed",AA16-L16,README!$B$4-L16) | T16: =IF(AND(Q16<>"Closed",Q16<>"Risk Accepted",O16<README!$B$4),"Yes","No") | U16: =IF(O16<>N16,"Yes","No") | V16: =IF(Q16="Risk Accepted","n/a (acceptance expiry)",IF(O16<=M16,"Yes","No")) | W16: Vendor responsiveness | X16: Inspection of vendor register (100% Tier 1–2 within frequency) and approved C-SCRM plan | AB16: Moderate (RISK-011 residual L2 x I4 = 8)
A17: POAM-016 | B17: FIND-016 | C17: SA-9; SR-6 | D17: RISK-010 | E17: Quarrystone: offshore PHI access, 30-day breach notice, excessive data fields, stale pentest | F17: 2023 contract on vendor paper before TPRM-007; self-attestation relied on; extract not designed for minimum necessary | G17: High | H17: Contract amendment (US-only + technical enforcement, 24h notice, subcontractor approval, data return/destruction 30 days with certificate, log cooperation); minimize extract to scoring-required fields with tokenized IDs; obtain current pentest + retest; SHCA data blocked until conditions met | I17: M1 Interim: vendor suspends offshore access to Wrenfield data (letter) (due 2026-07-24; Done) | M2 Execute contract amendment (redline v3 in negotiation) (due 2026-09-30; In Progress) | M3 Deploy minimized, tokenized extract (drop address, phone, email, free text) (due 2026-10-16; In Progress) | M4 Receive current pentest report + retest letter (EVID-051) (due 2026-10-30; Not Started) | M5 Assessor validation + vendor risk re-score (due 2026-11-05; Not Started) | J17: Dr. Miriam Castell (VP Clinical Analytics) | K17: General Counsel (about 20h); Data Engineering (about 60h for extract redesign); Vendor Mgmt | L17: 46241 | M17: =L17+IF(G17="Critical",30,IF(G17="High",90,IF(G17="Moderate",180,365))) | N17: 46331 | O17: 46331 | Q17: In Progress | R17: =IFERROR(COUNTIFS(Milestones!$A:$A,A17,Milestones!$E:$E,"Done")/COUNTIF(Milestones!$A:$A,A17),0) | S17: =IF(Q17="Closed",AA17-L17,README!$B$4-L17) | T17: =IF(AND(Q17<>"Closed",Q17<>"Risk Accepted",O17<README!$B$4),"Yes","No") | U17: =IF(O17<>N17,"Yes","No") | V17: =IF(Q17="Risk Accepted","n/a (acceptance expiry)",IF(O17<=M17,"Yes","No")) | W17: Vendor negotiation; Quarrystone model retraining on minimized fields | X17: Inspection of executed amendment; test: sample extract file schema vs approved minimum field list; inspection of pentest/retest; vendor attestation of US-only access with access-log sample | Y17: EVID-073; EVID-051 | AB17: Moderate target (RISK-010 residual L2 x I4 = 8); currently High | AC17: VR-001 (Critical) escalated to CEO 2026-07-17 per risk appetite; CEO approved conditional continuation 2026-07-22.
A18: POAM-017 | B18: FIND-017 | C18: PL-2 | D18: RISK-016 | E18: SSP outdated; overstates implementation of 27 of 61 controls | F18: SSP maintained as SOC 2 narrative; no update trigger on architecture change | G18: Low | H18: Rewrite SSP control-by-control from the validated matrix (SP 800-18 Rev. 2 structure); add architecture-change trigger in CMP-006 | I18: M1 SSP outline on SP 800-18r2 structure; boundary + data flows updated (due 2026-09-30; In Progress) | M2 Control implementation statements (61 controls) reviewed by owners (due 2026-11-30; Not Started) | M3 Approval by CTO (system owner); assessor validation (due 2026-12-15; Not Started) | J18: Priya Raman (Security Compliance Manager) | K18: GRC Manager (about 80h); control owner reviews | L18: 46241 | M18: =L18+IF(G18="Critical",30,IF(G18="High",90,IF(G18="Moderate",180,365))) | N18: 46371 | O18: 46371 | Q18: In Progress | R18: =IFERROR(COUNTIFS(Milestones!$A:$A,A18,Milestones!$E:$E,"Done")/COUNTIF(Milestones!$A:$A,A18),0) | S18: =IF(Q18="Closed",AA18-L18,README!$B$4-L18) | T18: =IF(AND(Q18<>"Closed",Q18<>"Risk Accepted",O18<README!$B$4),"Yes","No") | U18: =IF(O18<>N18,"Yes","No") | V18: =IF(Q18="Risk Accepted","n/a (acceptance expiry)",IF(O18<=M18,"Yes","No")) | W18: Control owners' review time | X18: Inspection: SSP statements traced to matrix determinations (sample 15 controls) | AB18: Low (RISK-016 residual)
A19: POAM-018 | B19: FIND-018 | C19: CM-3 | D19: RISK-014 | E19: Emergency and console changes bypass approval (3 of 25 sampled) | F19: Console/emergency paths rely on memory; no retro-approval tracking | G19: Moderate | H19: Auto-open retro-approval task on every emergency change with 2-day escalation; CloudTrail/EventBridge alerts on console changes to security groups and IAM; approval gate before deploy job | I19: M1 Retro-approval task automation for emergency changes (due 2026-08-28; Done) | M2 EventBridge alerts on console SG/IAM changes to on-call (due 2026-09-04; Not Started) | M3 Assessor validation: sample of emergency changes since M1 + alert test (due 2026-09-11; Not Started) | J19: Tomasz Wierzbicki (Director, Platform Engineering) | K19: SRE (about 24h) | L19: 46241 | M19: =L19+IF(G19="Critical",30,IF(G19="High",90,IF(G19="Moderate",180,365))) | N19: 46276 | O19: 46276 | Q19: In Progress | R19: =IFERROR(COUNTIFS(Milestones!$A:$A,A19,Milestones!$E:$E,"Done")/COUNTIF(Milestones!$A:$A,A19),0) | S19: =IF(Q19="Closed",AA19-L19,README!$B$4-L19) | T19: =IF(AND(Q19<>"Closed",Q19<>"Risk Accepted",O19<README!$B$4),"Yes","No") | U19: =IF(O19<>N19,"Yes","No") | V19: =IF(Q19="Risk Accepted","n/a (acceptance expiry)",IF(O19<=M19,"Yes","No")) | W19: SRE backlog capacity (competing with POAM-011) | X19: Test: all emergency changes since 2026-08-28 retro-approved within 2 business days; trigger a test SG change and confirm alert | AB19: Moderate (RISK-014 residual L2 x I3 = 6) | AC19: Overdue since 2026-09-11; needs CTO prioritization decision against POAM-011 (same SRE team).
A20: POAM-019 | B20: FIND-019 | C20: AT-2 | D20: RISK-015 | E20: Security awareness training completion 91%; suspension not enforced | F20: Reminders to users only; no manager escalation or enforcement | G20: Low | H20: Okta group rule enforcing suspension at 30 days overdue; manager escalation at 14 days; monthly completion reporting | I20: M1 Manager escalation at 14 days; enforcement group rule live (due 2026-08-21; Done) | M2 Reach >= 99% (documented leave exceptions) (due 2026-09-15; Done) | M3 Assessor validation of EVID-070 (leave records for 3 exceptions) (due 2026-09-30; In Progress) | J20: Denise Yamamoto (Director of People) | K20: People Ops (about 8h); IAM Engineer (about 4h) | L20: 46241 | M20: =L20+IF(G20="Critical",30,IF(G20="High",90,IF(G20="Moderate",180,365))) | N20: 46295 | O20: 46295 | Q20: Completed – Pending Validation | R20: =IFERROR(COUNTIFS(Milestones!$A:$A,A20,Milestones!$E:$E,"Done")/COUNTIF(Milestones!$A:$A,A20),0) | S20: =IF(Q20="Closed",AA20-L20,README!$B$4-L20) | T20: =IF(AND(Q20<>"Closed",Q20<>"Risk Accepted",O20<README!$B$4),"Yes","No") | U20: =IF(O20<>N20,"Yes","No") | V20: =IF(Q20="Risk Accepted","n/a (acceptance expiry)",IF(O20<=M20,"Yes","No")) | X20: Inspection: LMS roster reconciled to Okta active population; leave exceptions verified in PeopleHub | Y20: EVID-070 | AB20: Moderate, accepted (RISK-015 residual L3 x I3 = 9)

Sheet Milestones
A1: POA&M ID | B1: Milestone | C1: Description | D1: Due Date | E1: Status | F1: Completed Date | G1: Late?
A2: POAM-001 | B2: M1 | C2: Disable 4 identified accounts (AR-EX-01..04); investigate post-termination sign-in (INC-2026-0117) | D2: 46213 | E2: Done | F2: 46212 | G2: =IF(AND(E2<>"Done",D2<README!$B$4),"Yes","No")
A3: POAM-001 | B3: M2 | C3: Deploy daily HR-to-Okta/AWS IAM/portal reconciliation job with auto-ticketing | D3: 46255 | E3: Done | F3: 46237 | G3: =IF(AND(E3<>"Done",D3<README!$B$4),"Yes","No")
A4: POAM-001 | B4: M3 | C4: Update SOP-IAM-02 (24h SLA, local-account checklist, vendor portals); train IT | D4: 46262 | E4: Done | F4: 46260 | G4: =IF(AND(E4<>"Done",D4<README!$B$4),"Yes","No")
A5: POAM-001 | B5: M4 | C5: Assessor validation: re-perform termination test on all terminations since 2026-07-01 + 5 job runs | D5: 46276 | E5: Done | F5: 46275 | G5: =IF(AND(E5<>"Done",D5<README!$B$4),"Yes","No")
A6: POAM-002 | B6: M1 | C6: Enroll 9 human members in MFA (accommodation for 1) | D6: 46262 | E6: Done | F6: 46261 | G6: =IF(AND(E6<>"Done",D6<README!$B$4),"Yes","No")
A7: POAM-002 | B7: M2 | C7: Convert svc-vulnscan and svc-confroom to non-interactive integrations | D7: 46262 | E7: Done | F7: 46261 | G7: =IF(AND(E7<>"Done",D7<README!$B$4),"Yes","No")
A8: POAM-002 | B8: M3 | C8: Delete Legacy Exemption Policy and group; phishing-resistant policy on admin apps (CHG-2026-0731) | D8: 46266 | E8: Done | F8: 46262 | G8: =IF(AND(E8<>"Done",D8<README!$B$4),"Yes","No")
A9: POAM-002 | B9: M4 | C9: Assessor validation: policy export, group lookup, password-only sign-in attempt, IAM credential report | D9: 46270 | E9: Done | F9: 46270 | G9: =IF(AND(E9<>"Done",D9<README!$B$4),"Yes","No")
A10: POAM-003 | B10: M1 | C10: Remove excess grants: AR-EX-05/06/07/08/09 | D10: 46255 | E10: Done | F10: 46254 | G10: =IF(AND(E10<>"Done",D10<README!$B$4),"Yes","No")
A11: POAM-003 | B11: M2 | C11: Issue -adm accounts for remaining admins; remove admin from daily accounts (AR-EX-10) | D11: 46295 | E11: In Progress | G11: =IF(AND(E11<>"Done",D11<README!$B$4),"Yes","No")
A12: POAM-003 | B12: M3 | C12: Implement JIT elevation (approval + 4h auto-expiry) for AWS AdministratorAccess | D12: 46318 | E12: In Progress | G12: =IF(AND(E12<>"Done",D12<README!$B$4),"Yes","No")
A13: POAM-003 | B13: M4 | C13: Assessor validation: assignment export + live elevation record with CloudTrail evidence | D13: 46331 | E13: Not Started | G13: =IF(AND(E13<>"Done",D13<README!$B$4),"Yes","No")
A14: POAM-004 | B14: M1 | C14: Revoke duplicate, transferred, and inactive access (AR-EX-12/13/14) | D14: 46220 | E14: Done | F14: 46217 | G14: =IF(AND(E14<>"Done",D14<README!$B$4),"Yes","No")
A15: POAM-004 | B15: M2 | C15: Add transfer trigger to SOP-IAM-02 (re-baseline access within 5 business days) | D15: 46262 | E15: Done | F15: 46259 | G15: =IF(AND(E15<>"Done",D15<README!$B$4),"Yes","No")
A16: POAM-004 | B16: M3 | C16: Run Q3 privileged certification on new design (EVID-074) | D16: 46295 | E16: In Progress | G16: =IF(AND(E16<>"Done",D16<README!$B$4),"Yes","No")
A17: POAM-004 | B17: M4 | C17: Assessor validation: review Q3 campaign decisions for flagged items and rationale quality | D17: 46326 | E17: Not Started | G17: =IF(AND(E17<>"Done",D17<README!$B$4),"Yes","No")
A18: POAM-005 | B18: M1 | C18: Assign owners to all 13 non-human accounts; add fields to register | D18: 46255 | E18: Done | F18: 46252 | G18: =IF(AND(E18<>"Done",D18<README!$B$4),"Yes","No")
A19: POAM-005 | B19: M2 | C19: Rotate svc-quarrystone-sftp key (AR-EX-18) | D19: 46262 | E19: Done | F19: 46259 | G19: =IF(AND(E19<>"Done",D19<README!$B$4),"Yes","No")
A20: POAM-005 | B20: M3 | C20: Replace ironpeak-soc shared login with 6 named federated accounts (AR-EX-20) | D20: 46269 | E20: Done | F20: 46265 | G20: =IF(AND(E20<>"Done",D20<README!$B$4),"Yes","No")
A21: POAM-005 | B21: M4 | C21: Migrate svc-reporting-etl to IAM role; delete IAM user (AR-EX-19) | D21: 46276 | E21: Done | F21: 46268 | G21: =IF(AND(E21<>"Done",D21<README!$B$4),"Yes","No")
A22: POAM-005 | B22: M5 | C22: Assessor validation: register re-test (owner + credential age) and IAM credential report | D22: 46277 | E22: Done | F22: 46277 | G22: =IF(AND(E22<>"Done",D22<README!$B$4),"Yes","No")
A23: POAM-006 | B23: M1 | C23: Execute SOW amendment for awu; revoke out-of-scope PHI access (AR-EX-15/16) | D23: 46227 | E23: Done | F23: 46225 | G23: =IF(AND(E23<>"Done",D23<README!$B$4),"Yes","No")
A24: POAM-006 | B24: M2 | C24: Set Okta expiry for all contractor accounts; add SOW-scope field to access request form | D24: 46262 | E24: Done | F24: 46258 | G24: =IF(AND(E24<>"Done",D24<README!$B$4),"Yes","No")
A25: POAM-006 | B25: M3 | C25: Assessor validation: expiry report vs SOW register | D25: 46275 | E25: Done | F25: 46273 | G25: =IF(AND(E25<>"Done",D25<README!$B$4),"Yes","No")
A26: POAM-007 | B26: M1 | C26: Sign RACC-001 (CFO as risk owner; CISO concurrence) | D26: 46248 | E26: Done | F26: 46246 | G26: =IF(AND(E26<>"Done",D26<README!$B$4),"Yes","No")
A27: POAM-007 | B27: M2 | C27: Continue monthly compensating review (evidence each month to GRC) | D27: 46477 | E27: In Progress | G27: =IF(AND(E27<>"Done",D27<README!$B$4),"Yes","No")
A28: POAM-007 | B28: M3 | C28: Split roles at AP backfill (requisition open) | D28: 46477 | E28: Not Started | G28: =IF(AND(E28<>"Done",D28<README!$B$4),"Yes","No")
A29: POAM-008 | B29: M1 | C29: Change S3 lifecycle to 400-day expiry with Glacier IR after 90d (CHG-2026-0702) | D29: 46255 | E29: Done | F29: 46253 | G29: =IF(AND(E29<>"Done",D29<README!$B$4),"Yes","No")
A30: POAM-008 | B30: M2 | C30: Subscribe app-audit CloudWatch logs to log-archive (Firehose) | D30: 46262 | E30: Done | F30: 46261 | G30: =IF(AND(E30<>"Done",D30<README!$B$4),"Yes","No")
A31: POAM-008 | B31: M3 | C31: Assessor validation: config inspection + oldest-object query | D31: 46280 | E31: Done | F31: 46277 | G31: =IF(AND(E31<>"Done",D31<README!$B$4),"Yes","No")
A32: POAM-009 | B32: M1 | C32: Expand SIEM report scope to all privileged principals incl. IAM users | D32: 46255 | E32: Done | F32: 46248 | G32: =IF(AND(E32<>"Done",D32<README!$B$4),"Yes","No")
A33: POAM-009 | B33: M2 | C33: Auto-create weekly review ticket with escalation to CISO at 5 business days | D33: 46262 | E33: Done | F33: 46262 | G33: =IF(AND(E33<>"Done",D33<README!$B$4),"Yes","No")
A34: POAM-009 | B34: M3 | C34: Execute MDR SOW change for backup reviewer | D34: 46276 | E34: Delayed | G34: =IF(AND(E34<>"Done",D34<README!$B$4),"Yes","No")
A35: POAM-009 | B35: M4 | C35: Assessor validation: W27–W37 reviews (EVID-072) | D35: 46280 | E35: Not Started | G35: =IF(AND(E35<>"Done",D35<README!$B$4),"Yes","No")
A36: POAM-010 | B36: M1 | C36: Submit VM-003 §7 exception for 2 notify-worker criticals with reachability analysis (CISO decision) | D36: 46255 | E36: Done | F36: 46254 | G36: =IF(AND(E36<>"Done",D36<README!$B$4),"Yes","No")
A37: POAM-010 | B37: M2 | C37: Upgrade notify-worker to supported Node.js LTS + current base image | D37: 46295 | E37: In Progress | G37: =IF(AND(E37<>"Done",D37<README!$B$4),"Yes","No")
A38: POAM-010 | B38: M3 | C38: SLA-breach dashboard reviewed in weekly engineering leads meeting | D38: 46280 | E38: Done | F38: 46274 | G38: =IF(AND(E38<>"Done",D38<README!$B$4),"Yes","No")
A39: POAM-010 | B39: M4 | C39: Tag-policy SCP denying untagged EC2/EKS launches (OBS-02) | D39: 46310 | E39: Not Started | G39: =IF(AND(E39<>"Done",D39<README!$B$4),"Yes","No")
A40: POAM-010 | B40: M5 | C40: Assessor validation: re-run SLA test on Q3 population | D40: 46331 | E40: Not Started | G40: =IF(AND(E40<>"Done",D40<README!$B$4),"Yes","No")
...
