Workbook

Sheet README
A1: Wrenfield GRC Workbook: all artifacts, one governance system
A2: Wrenfield Health (fictional) · simulated NIST SP 800-53 Rev. 5 (Release 5.2.0) assessment · synthetic data
A4: As-of (status) date | B4: 46283 | C4: <- input: all aging/overdue formulas reference this cell (use =TODAY() in a live workbook)
A6: Sheets | B6: Dashboard (live formulas) · Controls · Risks · Findings · POAM · Milestones · Evidence · AccessReview · VendorInventory · VendorAssessment · VendorFindings · Lists
A7: Why one workbook | B7: Cross-sheet formulas prove the artifacts share IDs: the Dashboard counts across sheets, so a status change anywhere updates management reporting
A8: Recalculation | B8: Built with openpyxl; Excel/Sheets/LibreOffice compute formulas on open (fullCalcOnLoad). Formula results were verified with pycel (tools/check_formulas.py)
A9: Source of truth | B9: data/*.yaml -> tools/build.py

Sheet Dashboard
A1: Executive Dashboard (live formulas)
A2: As of | B2: =README!$B$4
A4: Metric ID | B4: Metric | C4: Value | D4: Definition
A5: MET-01 | B5: Controls in scope | C5: =COUNTIF(Controls!$A$2:$A$500,"?*") | D5: Count of control rows
A6: MET-02 | B6: Controls assessed (excl. N/A) | C6: =COUNTIF(Controls!$V:$V,"Satisfied")+COUNTIF(Controls!$V:$V,"Other Than Satisfied") | D6: Result is Satisfied or Other Than Satisfied
A7: MET-03 | B7: Controls Satisfied | C7: =COUNTIF(Controls!$V:$V,"Satisfied") | D7: Result = Satisfied
A8: MET-03a | B8: % of assessed controls Satisfied | C8: =ROUND(C7/C6,2) | D8: MET-03 / MET-02
A9: MET-04a | B9: Validated: Implemented | C9: =COUNTIF(Controls!$M:$M,"Implemented") | D9: Assessor-validated status
A10: MET-04b | B10: Validated: Partially Implemented | C10: =COUNTIF(Controls!$M:$M,"Partially Implemented") | D10: Assessor-validated status
A11: MET-04c | B11: Validated: Planned or Not Implemented | C11: =COUNTIF(Controls!$M:$M,"Planned")+COUNTIF(Controls!$M:$M,"Not Implemented") | D11: Assessor-validated status
A12: MET-05 | B12: Controls where assessor changed owner-stated status | C12: =COUNTIF(Controls!$N:$N,"Yes") | D12: Owner overstatement indicator
A13: MET-06 | B13: Findings (total) | C13: =COUNTIF(Findings!$A$2:$A$500,"FIND-*") | D13: All findings
A14: MET-06a | B14: Open findings (not Closed / Risk Accepted) | C14: =C13-COUNTIF(Findings!$O:$O,"Closed")-COUNTIF(Findings!$O:$O,"Risk Accepted") | D14: Total minus Closed minus Risk Accepted
A15: MET-07 | B15: Open High/Critical findings | C15: =COUNTIFS(Findings!$C:$C,"High",Findings!$O:$O,"<>Closed")+COUNTIFS(Findings!$C:$C,"Critical",Findings!$O:$O,"<>Closed") | D15: Severity High/Critical and not Closed
A16: MET-08 | B16: Overdue POA&M items | C16: =COUNTIF(POAM!$T:$T,"Yes") | D16: Formula-driven Overdue? column
A17: MET-08a | B17: Slipped POA&M items (target changed) | C17: =COUNTIF(POAM!$U:$U,"Yes") | D17: Current target <> original target
A18: MET-09 | B18: POA&M closed and validated | C18: =COUNTIF(POAM!$Q:$Q,"Closed") | D18: Status Closed (requires validation)
A19: MET-10 | B19: Access-review exceptions (distinct) | C19: =SUM(AccessReview!$AD:$AD) | D19: Distinct AR-EX IDs (helper column counts each ID once)
A20: MET-10a | B20: Access-review exception rows | C20: =COUNTIF(AccessReview!$S:$S,"AR-EX-*") | D20: Rows carrying an exception
A21: MET-11 | B21: Vendor findings (VR) total | C21: =COUNTIF(VendorFindings!$A$2:$A$500,"VR-*") | D21: All VR items
A22: MET-11a | B22: Vendor findings Critical/High | C22: =COUNTIF(VendorFindings!$C:$C,"Critical")+COUNTIF(VendorFindings!$C:$C,"High") | D22: Severity
A23: MET-11b | B23: Tier 1-2 vendors with current assessment | C23: =COUNTIFS(VendorInventory!$K:$K,"<=2",VendorInventory!$O:$O,"Yes") | D23: Formula-driven currency
A24: MET-11c | B24: Tier 1-2 vendors total | C24: =COUNTIF(VendorInventory!$K:$K,"<=2") | D24: Tier from inherent score
A25: MET-12 | B25: Evidence completion % | C25: =ROUND((COUNTIF(Evidence!$I:$I,"Accepted")+COUNTIF(Evidence!$I:$I,"Closed"))/COUNTIF(Evidence!$A:$A,"EVID-*"),2) | D25: (Accepted + Closed) / requested
A26: MET-13a | B26: Enterprise risks rated High+ (current) | C26: =COUNTIF(Risks!$O:$O,"High")+COUNTIF(Risks!$O:$O,"Critical") | D26: Current (as tested)
A27: MET-13b | B27: Enterprise risks rated High+ (residual target) | C27: =COUNTIF(Risks!$W:$W,"High")+COUNTIF(Risks!$W:$W,"Critical") | D27: Residual target

Sheet Controls
A1: Control ID | B1: Control Family | C1: Control Name | D1: Baseline (SP 800-53B) | E1: Control Requirement Summary | F1: Applicability | G1: Applicability Rationale | H1: Control Origination | I1: System / Process | J1: Control Owner | K1: Business Requirements (REQ) | L1: Implementation Status (Owner-Stated) | M1: Implementation Status (Assessor-Validated) | N1: Status Changed by Assessor? | O1: Implementation Description | P1: Evidence Required | Q1: Evidence Available (EVID) | R1: Evidence Location | S1: Highest Evidence Level | T1: Testing Method | U1: Test Procedure / Expected vs Actual | V1: Assessment Result | W1: Gap Identified | X1: Risk Rating | Y1: Related Risk ID | Z1: Related Finding ID | AA1: Related POA&M ID | AB1: POA&M Status (as of status date) | AC1: Observations | AD1: Last Reviewed | AE1: Next Review | AF1: CSF 2.0 Function (informal) | AG1: Notes
A2: AC-1 | B2: AC - Access Control | C2: Policy and Procedures | D2: Moderate | E2: Develop, document, and disseminate an access control policy and procedures; designate an official to manage them; review and update them at a defined frequency and after defined events. | F2: Applicable | H2: Common (organization-wide) | I2: All in-scope systems | J2: Alicia Moreno (CISO) | K2: REQ-001; REQ-014; REQ-024 | L2: Implemented | M2: Implemented | N2: =IF(L2<>M2,"Yes","No") | O2: Access Control Policy ACP-002 v3.1 (approved 2025-01-15 by the CISO) covers account types, approvals, least privilege, separate admin accounts (§5.4), 24h de-provisioning (§5.3), inactivity (§5.6), and quarterly privileged recertification. It is published on the intranet and acknowledged at onboarding. JML procedure SOP-IAM-02 v2.0 implements it. | P2: Current approved policy and procedures, approval record, review history, dissemination evidence | Q2: EVID-001; EVID-002 | R2: GRC-Vault:/WCP-2026/AC/EVID-001_ACP-002_v3.1.pdf; GRC-Vault:/WCP-2026/AC/EVID-002_SOP-IAM-02_v2.0.pdf | S2: Design | T2: Examine, Interview | U2: Examined ACP-002 v3.1 and SOP-IAM-02 v2.0 against the AC family requirements, and interviewed the CISO. Expected: policy reviewed within the 12-month cycle. Actual: the last approved review was 2025-01-15, so it is 5 months overdue. Draft v3.2 has been in review since 2026-05. Content is adequate, and policy statements are specific enough to test (they drove several findings). | V2: Satisfied | W2: Annual review overdue by about 5 months (below the finding threshold: the content is current and the draft is in approval). | X2: Low | AB2: n/a | AC2: OBS-01 | AD2: 46220 | AE2: 46583 | AF2: PR | AG2: A policy existing does not prove the controls operate. AC-2/AC-6 test results show several ACP-002 requirements not operating.
A3: AC-2 | B3: AC - Access Control | C3: Account Management | D3: Moderate | E3: Define allowed account types; assign account managers; require approvals for account creation; create, modify, disable, and remove accounts per defined conditions; monitor account use; notify account managers when accounts are no longer needed; review accounts for compliance at a defined frequency. | F3: Applicable | H3: Hybrid (Okta common control + system-specific accounts) | I3: SYS-01, SYS-02, SYS-03, SYS-04, SYS-05, SYS-06, SYS-07, SYS-08, SYS-09 | J3: Nadia Rahman (IAM Engineer) | K3: REQ-001; REQ-004; REQ-013; REQ-014; REQ-023 | L3: Implemented | M3: Partially Implemented | N3: =IF(L3<>M3,"Yes","No") | O3: Okta is the identity source for SSO apps. Access requests go through Jira service desk tickets approved by the manager and the system owner. Termination tickets are raised manually by IT from HR emails. Local accounts exist outside Okta on AWS (legacy IAM users), wf-sftp-01, and the Quarrystone portal, and are managed ad hoc. There is a service-account register, but it lacked owner and rotation fields until 2026-07. | P3: Account-management procedure; user and entitlement populations from each system; HR roster; service-account register; recertification records | Q3: EVID-002; EVID-005; EVID-006; EVID-007; EVID-013; EVID-061; EVID-065 | R3: GRC-Vault:/WCP-2026/AC/EVID-002_SOP-IAM-02_v2.0.pdf; access-review/source-exports/okta_users.csv; access-review/source-exports/entitlements.csv; evidence/IA/EVID-007_aws-iam-credential-report_2026-06-30.csv; access-review/source-exports/service_accounts.csv; evidence/AC/EVID-061_terminations-and-deactivations_2026-07-01_to_09-09.csv; GRC-Vault:/WCP-2026/IA/EVID-065_service-register-v2026-09.csv | S3: Operating Effectiveness | T3: Examine, Interview, Test | U3: Full reconciliation of 106 entitlements on 9 systems against HR, the role baseline, the SoD rules, and the service register (tools/review_engine.py). Expected: every account is authorized, owned, and current. Actual: 20 exceptions across 28 entitlement rows. They include terminated users (4), a duplicate identity, inactive access, contractor term drift, service accounts without owners or rotation, and a shared vendor login. | V3: Other Than Satisfied | W3: Account lifecycle is not enforced for local (non-SSO) accounts, contractors, transfers, or service accounts. Account reviews did not catch these. | X3: High | Y3: RISK-002; RISK-004; RISK-017 | Z3: FIND-001; FIND-004; FIND-005; FIND-006 | AA3: POAM-001; POAM-004; POAM-005; POAM-006 | AB3: POAM-001: Closed; POAM-004: In Progress; POAM-005: Closed; POAM-006: Closed | AD3: 46220 | AE3: 46371 | AF3: PR | AG3: Anchor control for the access review. Individual exceptions roll up into 4 findings by root cause.
A4: AC-2(1) | B4: AC - Access Control | C4: Automated System Account Management | D4: Moderate | E4: Support management of system accounts with automated mechanisms. | F4: Applicable | H4: Common (Okta) | I4: SYS-02, SYS-06 | J4: Nadia Rahman (IAM Engineer) | K4: REQ-004; REQ-013 | L4: Implemented | M4: Partially Implemented | N4: =IF(L4<>M4,"Yes","No") | O4: Okta provisions users to GitHub and AWS IAM Identity Center with SCIM and group push. The PeopleHub-to-Okta integration syncs attributes only. Terminations and contract end dates did not trigger de-provisioning before 2026-08, and contractor accounts had no expiry dates. | P4: Integration configuration; provisioning and de-provisioning logs; evidence that HR events trigger account actions | Q4: EVID-004; EVID-005; EVID-062 | R4: evidence/AC/EVID-004_okta-deactivation-events-2026H1.csv; access-review/source-exports/okta_users.csv; evidence/AC/EVID-062_hr-okta-reconciliation-job_2026-09-10.csv | S4: Implementation | T4: Examine, Interview | U4: Examined the Okta-PeopleHub integration settings and interviewed the IAM Engineer. Expected: HR termination events automatically trigger de-provisioning. Actual: sync was attribute-only, so de-provisioning was a manual ticket. This design gap is the root cause of FIND-001. Post-remediation: a daily reconciliation job with auto-ticketing (live 2026-08-03) and Okta account-expiry dates for contractors were verified in EVID-062. | V4: Other Than Satisfied | W4: No automated de-provisioning from the authoritative HR source (fixed with compensating automation; full lifecycle-management licensing is planned for FY27). | X4: High | Y4: RISK-002 | Z4: FIND-001 | AA4: POAM-001 | AB4: POAM-001: Closed | AD4: 46220 | AE4: 46583 | AF4: PR | AG4: The reconciliation job is a detective and ticketing automation, not true HR-driven de-provisioning. The status stays Partially Implemented until lifecycle automation is licensed.
A5: AC-2(3) | B5: AC - Access Control | C5: Disable Accounts | D5: Moderate | E5: Disable accounts within a defined period when they have expired, are no longer associated with a user or function, violate policy, or have been inactive for a defined period. | F5: Applicable | H5: Hybrid | I5: SYS-01, SYS-02, SYS-03, SYS-07, SYS-09 | J5: Nadia Rahman (IAM Engineer) | K5: REQ-004; REQ-013 | L5: Implemented | M5: Partially Implemented | N5: =IF(L5<>M5,"Yes","No") | O5: ACP-002 §5.3 requires disabling within 24 hours of termination, and §5.6 requires disabling after 90 days of inactivity. IT deactivates Okta accounts from manual tickets. There was no inactivity automation and no process for local accounts. | P5: Complete population of terminations in the period; de-provisioning logs for every system; inactivity report | Q5: EVID-003; EVID-004; EVID-007; EVID-061; EVID-062; EVID-064 | R5: evidence/AC/EVID-003_peoplehub-terminations-2026H1.csv; evidence/AC/EVID-004_okta-deactivation-events-2026H1.csv; evidence/IA/EVID-007_aws-iam-credential-report_2026-06-30.csv; evidence/AC/EVID-061_terminations-and-deactivations_2026-07-01_to_09-09.csv; evidence/AC/EVID-062_hr-okta-reconciliation-job_2026-09-10.csv; evidence/IA/EVID-064_aws-iam-credential-report_2026-09-04.csv | S5: Operating Effectiveness | T5: Examine, Test | U5: Re-performed the 24h test on all 19 H1 terminations (docs/assessment/test-results/termination-deprovisioning.md). Expected: 19 of 19 within 24h, including non-SSO accounts. Actual: 16 of 19 within SLA, 1 late (209h), 2 never deactivated (one with a post-termination sign-in, which became INC-2026-0117), plus 1 active local AWS IAM user and 1 Quarrystone portal account belonging to leavers. Validation re-test (2026-09-10): 7 of 7 within SLA, and the reconciliation job reported 0 exceptions. | V5: Other Than Satisfied | W5: De-provisioning depended on manual tickets and missed local accounts. | X5: High | Y5: RISK-002 | Z5: FIND-001 | AA5: POAM-001 | AB5: POAM-001: Closed | AD5: 46275 | AE5: 46583 | AF5: PR | AG5: Remediation validated 2026-09-10. Full re-test at the FY27 assessment because the post-fix operating sample is small (7).
A6: AC-5 | B6: AC - Access Control | C6: Separation of Duties | D6: Moderate | E6: Identify and document duties that require separation, and define system access authorizations that support that separation. | F6: Applicable | H6: System-specific (Ledgerline) | I6: SYS-07 | J6: Laura Brenneman (Controller) | K6: REQ-023; REQ-024 | L6: Implemented | M6: Partially Implemented | N6: =IF(L6<>M6,"Yes","No") | O6: Ledgerline has an SoD ruleset (SOD-01 vendor master vs payment approval; SOD-02 AP entry vs approval). After the AP Specialist left in 2026-05, the Senior Accountant held both Vendor Master Maintain and Payment Approver (<= $25k). The compensating control is a monthly vendor-master change report that the Controller reviews and signs. | P6: SoD matrix; role assignments; evidence of the compensating review for each month | Q6: EVID-014; EVID-015; EVID-060 | R6: access-review/source-exports/sod_rules.csv; GRC-Vault:/WCP-2026/AC/EVID-015_vendor-master-reviews-H1.pdf; risk/risk-acceptance/RACC-001.md | S6: Operating Effectiveness | T6: Examine, Interview, Test | U6: Tested role assignments against the SoD rules (review engine) and inspected 6 of 6 monthly compensating reviews (Jan–Jun). Expected: no user holds conflicting roles, or a documented and operating compensating control exists. Actual: 1 conflict (jmercer, SOD-01). The compensating review operated 6 of 6 months (signed, dated, 2 bank-detail changes independently verified by callback). The conflict was not formally risk-accepted until RACC-001 (2026-08-12). | V6: Other Than Satisfied | W6: Conflicting duties held by one user. The compensating control operates, but it was undocumented as a risk decision. | X6: Moderate | Y6: RISK-013 | Z6: FIND-007 | AA6: POAM-007 | AB6: POAM-007: Risk Accepted | AD6: 46220 | AE6: 46477 | AF6: PR | AG6: Formally accepted (RACC-001, CFO, expires 2027-03-31). This is the project's worked example of a compensating control plus risk acceptance.
A7: AC-6 | B7: AC - Access Control | C7: Least Privilege | D7: Moderate | E7: Employ the principle of least privilege, allowing only authorized accesses necessary to accomplish assigned tasks. | F7: Applicable | H7: Hybrid | I7: SYS-01, SYS-02, SYS-03, SYS-04 | J7: Tomasz Wierzbicki (Director, Platform Engineering) | K7: REQ-001; REQ-014; REQ-023 | L7: Implemented | M7: Partially Implemented | N7: =IF(L7<>M7,"Yes","No") | O7: A role-based access baseline exists (role_access_matrix). AWS permission sets are assigned through Okta groups. Temporary grants (for migrations and troubleshooting) have no expiry mechanism. | P7: Role baseline; entitlement exports; justification for privileged grants | Q7: EVID-006; EVID-016; EVID-017; EVID-075; EVID-076 | R7: access-review/source-exports/entitlements.csv; access-review/source-exports/entitlements.csv; access-review/source-exports/entitlements.csv; GRC-Vault:/WCP-2026/AC/EVID-075_idc-assignments-2026-09-03.csv; GRC-Vault:/WCP-2026/AC/EVID-076_github-owners-2026-08-12.csv | S7: Operating Effectiveness | T7: Examine, Test | U7: Compared every privileged and PHI entitlement to the role baseline. Expected: 0 grants outside the baseline without approved justification. Actual: 8 rows outside the baseline (F-BASELINE), all confirmed on review. 6 are excessive privileged grants (2 prod AdministratorAccess, 2 GitHub owners, 1 Okta Super Admin, 1 PHI database write) under FIND-003. The other 2 are PHI read access kept after a transfer (FIND-004) and PHI access outside a contractor's SOW (FIND-006). | V7: Other Than Satisfied | W7: Temporary privileged grants never expire; access is not re-baselined when roles change. | X7: High | Y7: RISK-001; RISK-004 | Z7: FIND-003 | AA7: POAM-003 | AB7: POAM-003: In Progress | AD7: 46220 | AE7: 46331 | AF7: PR
A8: AC-6(2) | B8: AC - Access Control | C8: Non-privileged Access for Nonsecurity Functions | D8: Moderate | E8: Require users of privileged accounts or roles to use non-privileged accounts or roles when accessing nonsecurity functions. | F8: Applicable | H8: Hybrid | I8: SYS-01, SYS-02 | J8: Nadia Rahman (IAM Engineer) | K8: REQ-003; REQ-014 | L8: Implemented | M8: Partially Implemented | N8: =IF(L8<>M8,"Yes","No") | O8: ACP-002 §5.4 (since 2025-07) requires separate -adm accounts for AWS prod AdministratorAccess and Okta Super Administrator. Two admins (jkim-adm, nrahman-adm) follow it. Others still hold admin roles on email and browsing accounts. | P8: List of privileged role holders with account type | Q8: EVID-005; EVID-016; EVID-075 | R8: access-review/source-exports/okta_users.csv; access-review/source-exports/entitlements.csv; GRC-Vault:/WCP-2026/AC/EVID-075_idc-assignments-2026-09-03.csv | S8: Implementation | T8: Examine, Test | U8: Tested account type for every holder of the two covered roles. Expected: all on -adm or break-glass accounts. Actual: 6 of 10 covered assignments were not on -adm or break-glass accounts (F-DAILYADMIN): 2 legitimate SRE holders (AR-EX-10), and 4 assignments that were also excessive or orphaned (AR-EX-03/05/06/09). | V8: Other Than Satisfied | W8: Separate admin accounts are required by policy but not implemented for most admins. | X8: High | Y8: RISK-001 | Z8: FIND-003 | AA8: POAM-003 | AB8: POAM-003: In Progress | AD8: 46220 | AE8: 46331 | AF8: PR
A9: AC-6(5) | B9: AC - Access Control | C9: Privileged Accounts | D9: Moderate | E9: Restrict privileged accounts on the system to defined personnel or roles. | F9: Applicable | H9: Hybrid | I9: SYS-01, SYS-02, SYS-03 | J9: Tomasz Wierzbicki (Director, Platform Engineering) | K9: REQ-003; REQ-014; REQ-023 | L9: Implemented | M9: Partially Implemented | N9: =IF(L9<>M9,"Yes","No") | O9: Defined privileged roles are SRE (AWS admin), IAM Engineer (Okta Super Admin), and CTO plus platform (up to 3 GitHub owners). Break-glass accounts are vaulted and tested quarterly. | P9: Privileged role definitions; complete privileged-account population per system | Q9: EVID-016; EVID-017; EVID-075; EVID-076; EVID-077 | R9: access-review/source-exports/entitlements.csv; access-review/source-exports/entitlements.csv; GRC-Vault:/WCP-2026/AC/EVID-075_idc-assignments-2026-09-03.csv; GRC-Vault:/WCP-2026/AC/EVID-076_github-owners-2026-08-12.csv; GRC-Vault:/WCP-2026/AC/EVID-077_okta-admin-roles-2026-07-21.csv | S9: Operating Effectiveness | T9: Examine, Test | U9: Enumerated all 37 privileged entitlements. Expected: every holder is in a defined privileged role. Actual: AWS prod AdministratorAccess had 6 human-linked holders (including a terminated employee's local IAM user) against 3 authorized SRE roles. GitHub owners were 5 against a maximum of 3. Okta Super Admin had 1 unauthorized holder. Break-glass accounts were well controlled (last tests 2026-04-15 and 2026-05-12). | V9: Other Than Satisfied | W9: More privileged holders than the defined roles allow. | X9: High | Y9: RISK-001 | Z9: FIND-003 | AA9: POAM-003 | AB9: POAM-003: In Progress | AD9: 46220 | AE9: 46331 | AF9: PR
A10: AC-6(7) | B10: AC - Access Control | C10: Review of User Privileges | D10: Moderate | E10: Review the privileges assigned to defined roles or classes of users at a defined frequency to validate the need for them, and reassign or remove privileges as necessary. | F10: Applicable | H10: Hybrid | I10: SYS-01, SYS-02, SYS-03, SYS-04 | J10: Alicia Moreno (CISO) | K10: REQ-004; REQ-014; REQ-023 | L10: Implemented | M10: Partially Implemented | N10: =IF(L10<>M10,"Yes","No") | O10: Quarterly Okta manager certification campaigns cover app-assignment level access only. AWS permission sets, GitHub roles, database roles, and local accounts were never in scope. Before this assessment, no privileged-access review existed. | P10: Review campaign exports showing population, reviewer, decision, date, and resulting changes | Q10: EVID-008; EVID-009; EVID-074 | R10: evidence/AC/EVID-008_q1-certification-summary.md; evidence/AC/EVID-009_insufficient-screenshot-example.md; GRC-Vault:/WCP-2026/AC/EVID-074_pending | S10: Operating Effectiveness | T10: Examine, Interview, Test | U10: Examined the Q1 2026 campaign export (412 decisions by 23 reviewers). Expected: complete population, meaningful decisions, and removals actioned. Actual: 100% approved, and 17 of 23 reviewers finished in under 5 minutes. The campaign approved rgupta2 (duplicate) and cfernandes's pre-transfer access. Privileged systems were out of scope. The dashboard screenshot first provided (EVID-009) was insufficient: no population, no decisions. | V10: Other Than Satisfied | W10: Recertification is incomplete in scope and ineffective in operation (rubber-stamping). | X10: Moderate | Y10: RISK-004 | Z10: FIND-004 | AA10: POAM-004 | AB10: POAM-004: In Progress | AD10: 46220 | AE10: 46326 | AF10: PR | AG10: This assessment's access review (106 rows, 9 systems) is the first complete privileged review. The Q3 campaign (EVID-074) is the first under the new design.
A11: AC-17 | B11: AC - Access Control | C11: Remote Access | D11: Moderate | E11: Establish usage restrictions, configuration requirements, and implementation guidance for each type of remote access, and authorize each type before allowing connections. | F11: Applicable | H11: Hybrid | I11: SYS-01, SYS-10 | J11: Tomasz Wierzbicki (Director, Platform Engineering) | K11: REQ-003 | L11: Implemented | M11: Implemented | N11: =IF(L11<>M11,"Yes","No") | O11: There is no network VPN into production. Administrative access uses AWS SSM Session Manager (sessions logged to log-archive) through IAM Identity Center, gated by Okta SSO+MFA from MDM-managed devices. No public bastions. wf-sftp-01 is administered through SSM only (except the RDP rule, reported under SC-7). | P11: Remote-access standard; SSM configuration; session logging; network exposure review | Q11: EVID-018; EVID-028 | R11: GRC-Vault:/WCP-2026/AC/EVID-018_ssm-session-prefs.json; GRC-Vault:/WCP-2026/CM/EVID-028_securityhub.csv | S11: Implementation | T11: Examine, Test | U11: Examined the SSM session preferences (logging to S3 and CloudWatch enabled, KMS-encrypted) and confirmed no security groups allow SSH from the internet except the documented SFTP allowlist. Expected: remote administration only through authenticated, logged channels. Actual: met. The RDP exposure on wf-sftp-01 is an unauthorized deviation, reported under SC-7 and CM-6, not a remote-access design flaw. | V11: Satisfied | AB11: n/a | AD11: 46220 | AE11: 46583 | AF11: PR
A12: AC-18 | B12: AC - Access Control | C12: Wireless Access | D12: Moderate | E12: Establish configuration and connection requirements for wireless access and authorize it before allowing connections. | F12: Not Applicable | G12: No wireless networking exists within the WCP-PROD boundary (AWS-hosted). Office Wi-Fi is outside the boundary and has no privileged path to production; production access from any network requires Okta SSO+MFA. Re-examine if the boundary changes. | H12: n/a | I12: n/a | J12: Tomasz Wierzbicki (Director, Platform Engineering) | K12: REQ-001 | L12: Not Applicable | M12: Not Applicable | N12: =IF(L12<>M12,"Yes","No") | O12: n/a (see applicability rationale) | P12: Boundary definition confirming no wireless components | Q12: EVID-040 | R12: docs/scope/system-profile.md | S12: Design | T12: Examine | U12: Examined the boundary diagram and the AWS network inventory. No wireless components are inside the boundary. N/A determination recorded in the scope statement. | V12: Not Assessed | AB12: n/a | AD12: 46220 | AE12: 46583 | AF12: PR
A13: AT-2 | B13: AT - Awareness and Training | C13: Literacy Training and Awareness | D13: Moderate | E13: Provide security and privacy literacy training to users at onboarding and at a defined frequency after that; include practical exercises (such as phishing simulations); update content after defined events. | F13: Applicable | H13: Common (organization-wide) | I13: All workforce | J13: Denise Yamamoto (Director of People) | K13: REQ-015 | L13: Implemented | M13: Partially Implemented | N13: =IF(L13<>M13,"Yes","No") | O13: Annual HIPAA and security awareness module in the LMS, plus quarterly phishing simulations. Policy requires completion within 30 days of assignment and suspends access after 30 days overdue, but the suspension is not enforced. | P13: LMS completion report for the full workforce; phishing simulation results; escalation records | Q13: EVID-019 | R13: GRC-Vault:/WCP-2026/AT/EVID-019_lms-completion-2026-06-30.csv | S13: Operating Effectiveness | T13: Examine, Test | U13: Compared the LMS roster (347) to the Okta active population. Expected: 100% completion (or documented exceptions). Actual: 316 of 347 (91%); 31 overdue, 4 of them with PHI data-store access. Phishing simulations ran 2 of 2 quarters (click rate 6.1% to 4.3%). Post-remediation: 344 of 347 (3 on leave) is under review (EVID-070). | V13: Other Than Satisfied | W13: Completion enforcement not operating. | X13: Low | Y13: RISK-015 | Z13: FIND-019 | AA13: POAM-019 | AB13: POAM-019: Completed – Pending Validation | AD13: 46220 | AE13: 46310 | AF13: GV
A14: AT-3 | B14: AT - Awareness and Training | C14: Role-based Training | D14: Moderate | E14: Provide role-based security and privacy training to personnel with assigned roles before authorizing access, and at a defined frequency after that. | F14: Applicable | H14: Common (organization-wide) | I14: Engineering, SRE, Clinical Ops, Security | J14: Denise Yamamoto (Director of People) | K14: REQ-015 | L14: Implemented | M14: Implemented | N14: =IF(L14<>M14,"Yes","No") | O14: Secure-coding training (annual) for engineers; privileged-user training for admins; HIPAA minimum-necessary training for clinical and support staff. Tracked in the LMS by role group. | P14: Role-based curricula and completion by role group | Q14: EVID-020 | R14: GRC-Vault:/WCP-2026/AT/EVID-020_role-training.csv | S14: Operating Effectiveness | T14: Examine, Test | U14: Sampled 15 role holders (5 engineers, 5 admins, 5 support/clinical). Expected: role training complete before access, or within 30 days of the role change. Actual: 15 of 15 complete. One admin completed 9 days after receiving admin access, within the 30-day grace in the training standard. | V14: Satisfied | AB14: n/a | AD14: 46220 | AE14: 46583 | AF14: GV
A15: AU-2 | B15: AU - Audit and Accountability | C15: Event Logging | D15: Moderate | E15: Identify the event types the system can log; coordinate logging with other entities; specify the event types to be logged; review and update the selection at a defined frequency. | F15: Applicable | H15: System-specific | I15: SYS-01, SYS-02, SYS-03, SYS-04 | J15: Owen Castillo (Security Engineer) | K15: REQ-019; REQ-005 | L15: Implemented | M15: Implemented | N15: =IF(L15<>M15,"Yes","No") | O15: Logging & Monitoring Standard LMS-004 defines required events. Sources include the AWS Organizations CloudTrail trail (management and S3 data events for PHI buckets), EKS audit logs, Aurora database activity logging for PHI tables, the application audit catalog (PHI view/export/print events with user, patient ID, and timestamp), and Okta and GitHub audit logs forwarded to the SIEM. | P15: Logging standard; trail configurations; sample events for each required type | Q15: EVID-021 | R15: GRC-Vault:/WCP-2026/AU/EVID-021_logging-config-and-samples.zip | S15: Implementation | T15: Examine, Test | U15: Traced 10 required event types (for example, PHI record view, bulk export, IAM policy change, Okta admin role grant) from action to SIEM. Expected: each event recorded with who, what, when, and where. Actual: 10 of 10 found with required fields. The event catalog was last reviewed 2026-02. | V15: Satisfied | AB15: n/a | AD15: 46220 | AE15: 46583 | AF15: DE
A16: AU-6 | B16: AU - Audit and Accountability | C16: Audit Record Review, Analysis, and Reporting | D16: Moderate | E16: Review and analyze audit records at a defined frequency for signs of inappropriate or unusual activity; report findings to defined personnel; adjust review when risk changes. | F16: Applicable | H16: System-specific | I16: SYS-01, SYS-02, SYS-08 | J16: Owen Castillo (Security Engineer) | K16: REQ-019; REQ-005 | L16: Implemented | M16: Partially Implemented | N16: =IF(L16<>M16,"Yes","No") | O16: MDR monitors alerts 24x7 (SI-4). Separately, LMS-004 §6 requires a weekly human review of privileged activity (AWS admin actions, Okta admin changes, GitHub owner actions), documented in a SEC ticket. One primary reviewer, no designated backup. | P16: Weekly review tickets for the whole period with dispositions | Q16: EVID-022; EVID-072 | R16: evidence/AU/EVID-022_privileged-activity-reviews-2026H1.csv; GRC-Vault:/WCP-2026/AU/EVID-072_reviews-W27-W37.csv | S16: Operating Effectiveness | T16: Examine, Test | U16: Tested all 26 weeks (test-results/au6-log-review.md). Expected: 26 of 26 performed within 5 days with every flag dispositioned. Actual: 19 performed and 17 fully effective (65%). 7 weeks were missed (migration, PTO) and 2 reviews were marked 'reviewed' with undispositioned flags. The review scope also excluded local IAM users. | V16: Other Than Satisfied | W16: Key detective review has a single point of failure and incomplete scope. | X16: Moderate | Y16: RISK-005 | Z16: FIND-009 | AA16: POAM-009 | AB16: POAM-009: In Progress | AD16: 46220 | AE16: 46326 | AF16: DE
A17: AU-9 | B17: AU - Audit and Accountability | C17: Protection of Audit Information | D17: Moderate | E17: Protect audit information and logging tools from unauthorized access, modification, and deletion; alert on detected unauthorized access, modification, or deletion. | F17: Applicable | H17: System-specific | I17: SYS-01 | J17: Owen Castillo (Security Engineer) | K17: REQ-019 | L17: Implemented | M17: Implemented | N17: =IF(L17<>M17,"Yes","No") | O17: CloudTrail and audit logs are delivered to a dedicated log-archive account. The S3 bucket uses Object Lock in compliance mode, a bucket policy denying deletes, and an SCP blocking StopLogging and DeleteTrail for all non-break-glass principals. The SIEM admin role is limited to 1 person, plus MDR read access. | P17: Log bucket configuration; SCPs; access list for the log account | Q17: EVID-023 | R17: GRC-Vault:/WCP-2026/AU/EVID-023_log-archive-protections.json | S17: Implementation | T17: Examine, Test | U17: Examined Object Lock and the SCPs. Using the assessor's read-only role, confirmed an attempt to call cloudtrail:StopLogging returns AccessDenied (explicit SCP deny). Expected: logs are immutable to operational admins. Actual: met. | V17: Satisfied | AB17: n/a | AD17: 46220 | AE17: 46583 | AF17: DE
A18: AU-11 | B18: AU - Audit and Accountability | C18: Audit Record Retention | D18: Moderate | E18: Retain audit records for a defined period consistent with records-retention policy to support after-the-fact investigations and meet regulatory and organizational retention requirements. | F18: Applicable | H18: System-specific | I18: SYS-01, SYS-08 | J18: Owen Castillo (Security Engineer) | K18: REQ-005; REQ-019 | L18: Implemented | M18: Partially Implemented | N18: =IF(L18<>M18,"Yes","No") | O18: At assessment: SIEM hot retention 90 days; the log-archive S3 lifecycle expired CloudTrail at 180 days; CloudWatch application-audit (PHI access) logs were kept 90 days with no archive. The CSA requires 12 months (90 days searchable). | P18: Retention settings for every audit source, and confirmation that the oldest available records match the setting | Q18: EVID-024; EVID-067 | R18: evidence/AU/EVID-024_log-retention-config_2026-06-30.json; evidence/AU/EVID-067_log-retention-config_2026-09-12.json | S18: Implementation | T18: Examine, Test | U18: Examined the retention configuration for 5 sources and queried the oldest available record in each. Expected: 12 months or more for all. Actual: CloudTrail 180 days, app audit 90 days, SIEM 90 days (the oldest records matched the settings, so there was no hidden longer retention). Validation (2026-09-12): lifecycle changed to a 400-day expiry, app audit is archived to log-archive, and objects dated 2026-03-20 (182 days old) are still present, confirming the old rule no longer applies. | V18: Other Than Satisfied | W18: Retention below the contractual 12 months. | X18: Moderate | Y18: RISK-005 | Z18: FIND-008 | AA18: POAM-008 | AB18: POAM-008: Closed | AD18: 46277 | AE18: 46583 | AF18: DE | AG18: Closure rests on configuration plus an early indicator. Full 12-month retention can only be demonstrated over time, so the FY27 assessment re-tests the oldest record date.
A19: CA-2 | B19: CA - Assessment, Authorization, and Monitoring | C19: Control Assessments | D19: Moderate | E19: Select an appropriate assessor or team; develop an assessment plan; assess controls at a defined frequency; produce an assessment report; provide results to defined individuals or roles. | F19: Applicable | H19: Common (organization-wide) | I19: WCP-PROD | J19: Priya Raman (Security Compliance Manager) | K19: REQ-002; REQ-012 | L19: Implemented | M19: Implemented | N19: =IF(L19<>M19,"Yes","No") | O19: Annual SOC 2 Type II examination by an independent CPA firm, an annual external penetration test (Lanternworks Security, fictional), and this SP 800-53 assessment (SAP ASMT-SAP-001). Results are reported to the CISO, CTO, and Audit & Risk Committee. | P19: Assessment plan; prior assessment reports; distribution evidence | Q19: EVID-025 | R19: GRC-Vault:/WCP-2026/CA/EVID-025_soc2-and-pentest.pdf | S19: Operating Effectiveness | T19: Examine, Interview | U19: Examined the SOC 2 report (unqualified; 1 exception noted in change management), the 2025 pentest summary (2 High findings, retest closed), and this engagement's SAP. Expected: independent assessments at a defined frequency with results reported. Actual: met. Note: SOC 2 does not test 800-53-specific requirements, which is why this engagement exists. | V19: Satisfied | AB19: n/a | AD19: 46220 | AE19: 46583 | AF19: GV
A20: CA-3 | B20: CA - Assessment, Authorization, and Monitoring | C20: Information Exchange | D20: Moderate | E20: Approve and manage information exchanges using defined agreement types; document interface characteristics, security and privacy requirements, controls, and responsibilities in the agreements; review and update them at a defined frequency. | F20: Applicable | H20: System-specific | I20: SYS-01, SYS-05 | J20: Liam Porter (Data Engineering Manager) | K20: REQ-018; REQ-021 | L20: Implemented | M20: Implemented | N20: =IF(L20<>M20,"Yes","No") | O20: Each interconnection has an agreement (BAA plus interface or data-sharing specification). The Quarrystone Data Sharing Specification v2 documents the fields, transfer method, schedule, encryption, and contacts. Customer EHR interfaces use per-customer interface specs. | P20: Interconnection inventory and agreement for each exchange | Q20: EVID-026 | R20: GRC-Vault:/WCP-2026/CA/EVID-026_interconnection-agreements.zip | S20: Design | T20: Examine | U20: Examined agreements for Quarrystone and 3 sampled customer EHR interfaces. Expected: signed agreement with security requirements and responsibilities for each exchange. Actual: all 4 present and signed. The Quarrystone spec's contents (excess fields, no US-only clause) are covered as vendor-risk issues under SA-9 (FIND-016), not as a missing agreement. | V20: Satisfied | AB20: n/a | AD20: 46220 | AE20: 46583 | AF20: GV | AG20: The determination separates having an exchange agreement (CA-3, met) from the adequacy of the vendor's terms (SA-9, not met).
A21: CA-5 | B21: CA - Assessment, Authorization, and Monitoring | C21: Plan of Action and Milestones | D21: Moderate | E21: Develop a plan of action and milestones documenting planned remediation of weaknesses found during control assessments; update it at a defined frequency based on assessment and monitoring results. | F21: Applicable | H21: Common (organization-wide) | I21: WCP-PROD | J21: Priya Raman (Security Compliance Manager) | K21: REQ-002 | L21: Implemented | M21: Implemented | N21: =IF(L21<>M21,"Yes","No") | O21: Before 2026-08, weaknesses were tracked in a Jira "SECISSUE" project with owners and due dates (SOC 2 remediation). Since 2026-08-07, the formal POA&M (poam/poam.xlsx) has been baselined, has milestones and SLAs, is reviewed biweekly, and is reported monthly to the CISO. | P21: POA&M; update history; evidence that items come from assessments and monitoring | Q21: EVID-027 | R21: GRC-Vault:/WCP-2026/CA/EVID-027_secissue-export.csv | S21: Implementation | T21: Examine | U21: Examined the prior Jira tracking (37 items, 100% with owner and due date; 4 overdue) and the new POA&M. Expected: all assessment weaknesses tracked with milestones. Actual: met. All 19 findings are in the POA&M, including the risk-accepted item. | V21: Satisfied | AB21: n/a | AD21: 46220 | AE21: 46583 | AF21: GV
A22: CA-7 | B22: CA - Assessment, Authorization, and Monitoring | C22: Continuous Monitoring | D22: Moderate | E22: Develop a system-level continuous monitoring strategy and implement monitoring with defined metrics, frequencies, ongoing assessments, correlation and analysis, response actions, and status reporting. | F22: Applicable | H22: Common (organization-wide) | I22: WCP-PROD | J22: Alicia Moreno (CISO) | K22: REQ-002; REQ-012 | L22: Implemented | M22: Implemented | N22: =IF(L22<>M22,"Yes","No") | O22: Operational monitoring is in place (Security Hub CIS checks, weekly vulnerability scans, GuardDuty and MDR, a monthly security metrics deck to the CTO). There is no formal written ISCM strategy document, and metrics were not tied to control objectives until the dashboard built in this engagement. | P22: ISCM strategy; monitoring outputs; reporting to management | Q22: EVID-028; EVID-058 | R22: GRC-Vault:/WCP-2026/CM/EVID-028_securityhub.csv; GRC-Vault:/WCP-2026/SI/EVID-058_monitoring.zip | S22: Operating Effectiveness | T22: Examine, Interview | U22: Examined 6 monthly metric decks and the Security Hub history. Expected: defined metrics reported at a defined frequency with response actions. Actual: monitoring and reporting operate. The CSPM alert on wf-sftp-01 went untriaged for 43 days, and that failure is recorded under SC-7/FIND-012. The strategy document gap is recorded as OBS-05. | V22: Satisfied | W22: No written ISCM strategy (observation). | X22: Low | Y22: RISK-016 | AB22: n/a | AC22: OBS-05 | AD22: 46220 | AE22: 46583 | AF22: GV
A23: CM-2 | B23: CM - Configuration Management | C23: Baseline Configuration | D23: Moderate | E23: Develop, document, and maintain a current baseline configuration under configuration control; review and update it at a defined frequency and when components are installed or upgraded. | F23: Applicable | H23: System-specific | I23: SYS-01 | J23: Tomasz Wierzbicki (Director, Platform Engineering) | K23: REQ-001; REQ-023 | L23: Implemented | M23: Implemented | N23: =IF(L23<>M23,"Yes","No") | O23: Infrastructure is defined in Terraform (baseline repo, PR-reviewed). EKS nodes use a hardened AMI (CIS Level 1) rebuilt monthly. Container base images are pinned and rebuilt weekly. The legacy hosts (wf-sftp-01, legacy-reports) have no managed baseline, which is recorded under SA-22. | P23: IaC baseline; AMI build specification; drift reports | Q23: EVID-029 | R23: GRC-Vault:/WCP-2026/CM/EVID-029_baseline.zip | S23: Implementation | T23: Examine, Test | U23: Examined the Terraform baseline and the AMI pipeline. Ran a drift check on 3 sampled modules (VPC, EKS, RDS). Expected: live config matches IaC. Actual: no drift in the sampled modules. The legacy hosts are outside IaC and are covered under SA-22. | V23: Satisfied | AB23: n/a | AD23: 46220 | AE23: 46583 | AF23: PR
A24: CM-3 | B24: CM - Configuration Management | C24: Configuration Change Control | D24: Moderate | E24: Determine and document types of changes that are configuration-controlled; review, approve or disapprove, document, and implement changes; retain records; monitor and review activities. | F24: Applicable | H24: System-specific | I24: SYS-01, SYS-03, SYS-05 | J24: Tomasz Wierzbicki (Director, Platform Engineering) | K24: REQ-023 | L24: Implemented | M24: Partially Implemented | N24: =IF(L24<>M24,"Yes","No") | O24: Code and IaC changes go through GitHub PRs with required reviews and CI, then deploy through a protected environment with approvers. The change management procedure CMP-006 requires emergency changes to be retro-approved within 2 business days. Console changes have no preventive gate. | P24: Change population for the period; sample tickets with approvals, reviews, tests, and deployment timestamps | Q24: EVID-030 | R24: evidence/CM/EVID-030_change-sample-2026H1.csv | S24: Operating Effectiveness | T24: Examine, Test | U24: Random sample of 25 of 212 changes (test-results/cm3-change-sample.md). Expected: 25 of 25 approved before deployment, or retro-approved within 2 business days for emergencies. Actual: 3 exceptions. CHG-2026-0412 (emergency RDP change, never approved or reverted), CHG-2026-0288 (retro approval after 9 days), and CHG-2026-0356 (deployed 5h38m before approval). | V24: Other Than Satisfied | W24: The emergency and console change paths bypass approval. | X24: Moderate | Y24: RISK-014 | Z24: FIND-018 | AA24: POAM-018 | AB24: POAM-018: In Progress | AD24: 46220 | AE24: 46387 | AF24: PR
A25: CM-6 | B25: CM - Configuration Management | C25: Configuration Settings | D25: Moderate | E25: Establish and document configuration settings using common secure configurations; implement them; identify, document, and approve deviations; monitor and control changes to settings. | F25: Applicable | H25: System-specific | I25: SYS-01, SYS-05 | J25: Tomasz Wierzbicki (Director, Platform Engineering) | K25: REQ-001 | L25: Implemented | M25: Partially Implemented | N25: =IF(L25<>M25,"Yes","No") | O25: AWS Security Hub runs the CIS AWS Foundations benchmark across accounts (97% of controls passing at 2026-06-30). Deviations are supposed to be triaged within 7 days (High) by SRE. The SRE on-call runbook did not include Security Hub findings, so triage depended on ad-hoc review. | P25: Secure configuration baseline; CSPM results and history; deviation approvals | Q25: EVID-028; EVID-053; EVID-068 | R25: GRC-Vault:/WCP-2026/CM/EVID-028_securityhub.csv; evidence/CM/EVID-053_wf-sftp-01-security-group_2026-07-02.json; GRC-Vault:/WCP-2026/SC/EVID-068_sg-fix.zip | S25: Operating Effectiveness | T25: Examine, Test | U25: Examined the Security Hub finding history. Expected: High deviations triaged within 7 days, or approved as exceptions. Actual: 3 High findings were open more than 30 days without triage, including 'Security group allows ingress from 0.0.0.0/0 to port 3389' on wf-sftp-01 (open 43 days). Remediated 2026-07-03; the security group and Security Hub re-evaluation were validated 2026-07-10 (EVID-068). | V25: Other Than Satisfied | W25: Deviation detection works; deviation response did not. | X25: High | Y25: RISK-012; RISK-007 | Z25: FIND-012 | AA25: POAM-012 | AB25: POAM-012: Closed | AD25: 46213 | AE25: 46583 | AF25: PR
A26: CM-8 | B26: CM - Configuration Management | C26: System Component Inventory | D26: Moderate | E26: Develop and document an accurate inventory of system components at the granularity needed for tracking and reporting; review and update it at a defined frequency. | F26: Applicable | H26: System-specific | I26: SYS-01, SYS-10 | J26: Tomasz Wierzbicki (Director, Platform Engineering) | K26: REQ-001 | L26: Implemented | M26: Implemented | N26: =IF(L26<>M26,"Yes","No") | O26: AWS Config aggregator (all accounts) plus the MDM inventory for endpoints. A tag policy requires owner, environment, and data-classification tags. | P26: Inventory exports; tag compliance; reconciliation to billing and resource counts | Q26: EVID-031 | R26: GRC-Vault:/WCP-2026/CM/EVID-031_inventory.zip | S26: Implementation | T26: Examine, Test | U26: Reconciled the AWS Config resource counts to Cost Explorer resource IDs for EC2, EKS, and RDS (100% present in inventory). Expected: complete inventory with ownership. Actual: inventory complete, but 7% of EC2/EKS resources lack an owner tag, which reduces scanner scoping accuracy (OBS-02). | V26: Satisfied | W26: Owner-tag compliance at 93% (observation). | X26: Low | Y26: RISK-006 | AB26: n/a | AC26: OBS-02 | AD26: 46220 | AE26: 46583 | AF26: ID
A27: CP-2 | B27: CP - Contingency Planning | C27: Contingency Plan | D27: Moderate | E27: Develop a contingency plan that identifies essential functions, recovery objectives, restoration priorities, roles, and contacts; distribute, review, update, and protect it. | F27: Applicable | H27: System-specific | I27: SYS-01 | J27: Tomasz Wierzbicki (Director, Platform Engineering) | K27: REQ-011; REQ-017 | L27: Implemented | M27: Implemented | N27: =IF(L27<>M27,"Yes","No") | O27: BC/DR Plan BCP-003 v2.1 (2025-11). RTO 4h and RPO 1h for WCP-PROD. Restoration priorities are the auth, care-plan, and RPM ingestion services. Covers clinical downtime procedures coordinated with customers. | P27: Approved current plan with defined RTO/RPO, roles, and distribution | Q27: EVID-032 | R27: GRC-Vault:/WCP-2026/CP/EVID-032_BCP-003_v2.1.pdf | S27: Design | T27: Examine, Interview | U27: Examined BCP-003 v2.1 against CP-2 elements. Expected: current, approved, with objectives and roles. Actual: met. The plan is sound on paper; whether it works is tested under CP-4 and CP-9(1). | V27: Satisfied | AB27: n/a | AD27: 46220 | AE27: 46583 | AF27: RC
A28: CP-4 | B28: CP - Contingency Planning | C28: Contingency Plan Testing | D28: Moderate | E28: Test the contingency plan at a defined frequency using defined tests to determine effectiveness and readiness; review results and initiate corrective actions. | F28: Applicable | H28: System-specific | I28: SYS-01 | J28: Tomasz Wierzbicki (Director, Platform Engineering) | K28: REQ-011; REQ-017 | L28: Implemented | M28: Not Implemented | N28: =IF(L28<>M28,"Yes","No") | O28: The owner cited a 2024 AZ-failover exercise. BCP-003 requires an annual test (tabletop or functional). No plan-level test was performed in the 12 months before fieldwork. | P28: Test plan, test records, after-action report, and corrective actions within the last 12 months | Q28: EVID-033 | R28: GRC-Vault:/WCP-2026/CP/EVID-033_az-failover-notes-2024.md | S28: Design | T28: Examine, Interview | U28: Requested all CP test records for the past 24 months. Expected: at least 1 plan-level test in the last 12 months. Actual: only 2024-04 engineering notes on an AZ failover (not a plan-level test, with no after-action report). Evidence was marked Insufficient. A combined ransomware tabletop (IR + CP) is scheduled for 2026-10-14. | V28: Other Than Satisfied | W28: Contingency plan not tested. | X28: Moderate | Y28: RISK-008 | Z28: FIND-014 | AA28: POAM-014 | AB28: POAM-014: In Progress | AD28: 46220 | AE28: 46326 | AF28: RC
A29: CP-9 | B29: CP - Contingency Planning | C29: System Backup | D29: Moderate | E29: Conduct backups of user-level, system-level, and security-related information at a defined frequency consistent with recovery objectives; protect the confidentiality, integrity, and availability of backups. | F29: Applicable | H29: System-specific | I29: SYS-01, SYS-04 | J29: Tomasz Wierzbicki (Director, Platform Engineering) | K29: REQ-011; REQ-017 | L29: Implemented | M29: Implemented | N29: =IF(L29<>M29,"Yes","No") | O29: Aurora continuous backup (PITR, 35 days), plus daily AWS Backup copies to the wcp-dr account in us-west-2 in a vault with Vault Lock (compliance mode) and KMS encryption. S3 versioning plus cross-region replication for documents. | P29: Backup plans; job history; vault protection settings; cross-region copies | Q29: EVID-034 | R29: GRC-Vault:/WCP-2026/CP/EVID-034_backup-config.zip | S29: Operating Effectiveness | T29: Examine, Test | U29: Examined the backup plans and 30 days of job history (30 of 30 successful), and confirmed Vault Lock plus cross-account copy. Expected: backups taken per RPO and protected from deletion. Actual: met. Whether backups can actually be restored is tested separately under CP-9(1). | V29: Satisfied | AB29: n/a | AD29: 46220 | AE29: 46583 | AF29: PR
A30: CP-9(1) | B30: CP - Contingency Planning | C30: Testing for Reliability and Integrity | D30: Moderate | E30: Test backup information at a defined frequency to verify media reliability and information integrity. | F30: Applicable | H30: System-specific | I30: SYS-04 | J30: Tomasz Wierzbicki (Director, Platform Engineering) | K30: REQ-011; REQ-017 | L30: Implemented | M30: Partially Implemented | N30: =IF(L30<>M30,"Yes","No") | O30: The owner treated backup-job success notifications as testing. No restore of wcp-core-db from the DR vault had been performed or documented. | P30: Restore test records showing restore steps, time taken, data-integrity checks, and results against RTO/RPO | Q30: EVID-035; EVID-069 | R30: GRC-Vault:/WCP-2026/CP/EVID-035_backup-job-notifications.pdf; evidence/CP/EVID-069_restore-test-record_2026-08-27.md | S30: Operating Effectiveness | T30: Examine, Test | U30: Expected: an annual documented restore test with integrity validation. Actual: none; job-success logs only (EVID-035, Insufficient). Validation: the assessor observed a restore test on 2026-08-27 (EVID-069). wcp-core-db was restored from the wcp-dr vault into an isolated account in 3h41m (RTO 4h). Data loss was 11 minutes (RPO 1h). Row-count and checksum validation passed on 12 tables. | V30: Other Than Satisfied | W30: Backup recoverability had never been demonstrated. | X30: Moderate | Y30: RISK-008 | Z30: FIND-013 | AA30: POAM-013 | AB30: POAM-013: Closed | AD30: 46266 | AE30: 46583 | AF30: RC
A31: IA-2 | B31: IA - Identification and Authentication | C31: Identification and Authentication (Organizational Users) | D31: Moderate | E31: Uniquely identify and authenticate organizational users and associate that identification with processes acting on their behalf. | F31: Applicable | H31: Common (Okta) | I31: SYS-02, and all SSO-integrated systems | J31: Nadia Rahman (IAM Engineer) | K31: REQ-020 | L31: Implemented | M31: Implemented | N31: =IF(L31<>M31,"Yes","No") | O31: Every workforce user has a unique Okta identity tied to an HR worker ID. Shared human accounts are prohibited (ACP-002 §4.2). The one shared vendor login found (ironpeak-soc) is reported under AC-2 and IA-5 as FIND-005. | P31: User population with unique identifiers mapped to HR | Q31: EVID-005 | R31: access-review/source-exports/okta_users.csv | S31: Implementation | T31: Examine, Test | U31: Mapped the Okta population to HR worker IDs. Expected: unique identity per person. Actual: met for workforce identities (the duplicate rgupta2 is one person with two accounts, handled under AC-2 and FIND-004). The shared EDR vendor login is handled under FIND-005. | V31: Satisfied | AB31: n/a | AD31: 46220 | AE31: 46583 | AF31: PR
A32: IA-2(1) | B32: IA - Identification and Authentication | C32: Multi-factor Authentication to Privileged Accounts | D32: Moderate | E32: Implement multi-factor authentication for access to privileged accounts. | F32: Applicable | H32: Hybrid (Okta + AWS IAM) | I32: SYS-01, SYS-02 | J32: Nadia Rahman (IAM Engineer) | K32: REQ-003; REQ-020 | L32: Implemented | M32: Partially Implemented | N32: =IF(L32<>M32,"Yes","No") | O32: The Okta global session policy requires MFA except for members of MFA-Exempt-Legacy (a 2023 policy). AWS Identity Center access inherits Okta MFA. Legacy IAM users authenticate directly to AWS. | P32: Authentication policies; exemption groups; privileged-user MFA status; AWS credential report | Q32: EVID-007; EVID-010; EVID-011; EVID-063; EVID-064 | R32: evidence/IA/EVID-007_aws-iam-credential-report_2026-06-30.csv; evidence/IA/EVID-010_okta-authentication-policies_2026-06-30.json; evidence/IA/EVID-011_okta-mfa-exempt-group_2026-06-30.csv; evidence/IA/EVID-063_okta-authentication-policies_2026-09-04.json; evidence/IA/EVID-064_aws-iam-credential-report_2026-09-04.csv | S32: Implementation | T32: Examine, Test | U32: Expected: 100% of privileged access requires MFA. Actual: 1 Okta Super Administrator (kbrandt) was in the exemption group, and the IAM user mfeld-admin (AdministratorAccess) had a console password without MFA. Validation (2026-09-04): the exemption policy and group were deleted, admin apps require phishing-resistant factors, and only aws-breakglass (hardware MFA) remains as an IAM user. A password-only sign-in was re-performed and denied. | V32: Other Than Satisfied | W32: MFA was bypassable for some privileged access. | X32: High | Y32: RISK-003; RISK-001 | Z32: FIND-002 | AA32: POAM-002 | AB32: POAM-002: Closed | AD32: 46270 | AE32: 46583 | AF32: PR
A33: IA-2(2) | B33: IA - Identification and Authentication | C33: Multi-factor Authentication to Non-privileged Accounts | D33: Moderate | E33: Implement multi-factor authentication for access to non-privileged accounts. | F33: Applicable | H33: Common (Okta) | I33: SYS-02 | J33: Nadia Rahman (IAM Engineer) | K33: REQ-003; REQ-020 | L33: Implemented | M33: Partially Implemented | N33: =IF(L33<>M33,"Yes","No") | O33: As for IA-2(1). The exemption group held 11 accounts (9 human, 2 service), added 2023–2025 for lost phones, SMS problems, shared clinic workstations, and a scanner. | P33: Authentication policy; exemption group membership with reasons and approvals | Q33: EVID-010; EVID-011; EVID-063 | R33: evidence/IA/EVID-010_okta-authentication-policies_2026-06-30.json; evidence/IA/EVID-011_okta-mfa-exempt-group_2026-06-30.csv; evidence/IA/EVID-063_okta-authentication-policies_2026-09-04.json | S33: Implementation | T33: Examine, Test | U33: Expected: 100% MFA, or time-bound approved exceptions. Actual: 9 of 347 human accounts (2.6%) exempt, and 0 of 11 exemptions had approval or expiry (the oldest dated 2023-05). Validation: all 9 enrolled (1 with a hardware key as an accessibility accommodation), both service accounts converted to non-interactive integrations, and the group deleted. | V33: Other Than Satisfied | W33: Permanent, unapproved MFA exemptions. | X33: High | Y33: RISK-003 | Z33: FIND-002 | AA33: POAM-002 | AB33: POAM-002: Closed | AD33: 46270 | AE33: 46583 | AF33: PR
A34: IA-2(8) | B34: IA - Identification and Authentication | C34: Access to Accounts — Replay Resistant | D34: Moderate | E34: Implement replay-resistant authentication mechanisms for access to privileged and non-privileged accounts. | F34: Applicable | H34: Common (Okta) | I34: SYS-02 | J34: Nadia Rahman (IAM Engineer) | K34: REQ-020 | L34: Implemented | M34: Implemented | N34: =IF(L34<>M34,"Yes","No") | O34: All enabled authenticators are replay-resistant (Okta Verify push with number challenge, FastPass, FIDO2/WebAuthn, TOTP). SMS, voice, email, and security questions have been disabled org-wide since 2025. | P34: Authenticator configuration | Q34: EVID-012; EVID-010 | R34: GRC-Vault:/WCP-2026/IA/EVID-012_okta-authenticators.json; evidence/IA/EVID-010_okta-authentication-policies_2026-06-30.json | S34: Implementation | T34: Examine | U34: Examined the enabled authenticators. Expected: only replay-resistant factors for users who authenticate with MFA. Actual: met. The exempt users under IA-2(1)/(2) did not use weak factors; they used no second factor at all. | V34: Satisfied | AB34: n/a | AD34: 46220 | AE34: 46583 | AF34: PR
A35: IA-5 | B35: IA - Identification and Authentication | C35: Authenticator Management | D35: Moderate | E35: Manage authenticators by verifying identity before distribution, establishing initial content, ensuring strength, managing lost or compromised authenticators, changing or refreshing them at defined frequencies, and protecting their content. | F35: Applicable | H35: Hybrid | I35: SYS-01, SYS-02, SYS-05, SYS-08 | J35: Nadia Rahman (IAM Engineer) | K35: REQ-020 | L35: Implemented | M35: Partially Implemented | N35: =IF(L35<>M35,"Yes","No") | O35: Human authenticators are strong (Okta password policy plus MFA; help-desk identity verification SOP). For service credentials, the standard requires rotation within 365 days or federation. Secrets Manager auto-rotates DB credentials, and CI/CD uses OIDC with no static keys. Some legacy service credentials are outside this. | P35: Password and authenticator policies; service credential inventory with rotation dates; help-desk verification records | Q35: EVID-007; EVID-013; EVID-064; EVID-065 | R35: evidence/IA/EVID-007_aws-iam-credential-report_2026-06-30.csv; access-review/source-exports/service_accounts.csv; evidence/IA/EVID-064_aws-iam-credential-report_2026-09-04.csv; GRC-Vault:/WCP-2026/IA/EVID-065_service-register-v2026-09.csv | S35: Operating Effectiveness | T35: Examine, Test | U35: Tested credential age for all 13 registered non-human accounts. Expected: none older than 365 days unless federated. Actual: 3 stale (svc-quarrystone-sftp SSH key 811 days; svc-reporting-etl access key 539 days; svc-vulnscan password since 2023), and 1 shared vendor password (ironpeak-soc). Sampled 5 help-desk MFA resets: 5 of 5 had identity verification recorded. | V35: Other Than Satisfied | W35: Long-lived static service credentials, and a shared credential. | X35: Moderate | Y35: RISK-017 | Z35: FIND-005 | AA35: POAM-005 | AB35: POAM-005: Closed | AD35: 46277 | AE35: 46583 | AF35: PR
